Workbook

Sheet DISPOSABLE ITEMS
A1: ITEM CODE | B1: ITEM NAME | C1: TYPE | D1: BODY PART | E1: DESCRIPTION | F1: MANUFACTURER | G1: STATUS | H1: LOT NO. | I1: EXP. DATE | J1: REMAINING QTY | K1: INPUT QTY | L1: OUT | M1: TOTAL | N1: 01-May | O1: 02-May | P1: 03-May | Q1: 04-May | R1: 05-May | S1: 06-May | T1: 07-May | U1: 08-May | V1: 09-May | W1: 10-May | X1: 11-May | Y1: 12-May | Z1: 13-May | AA1: 14-May | AB1: 15-May | AC1: 16-May | AD1: 17-May | AE1: 18-May | AF1: 19-May | AG1: 20-May | AH1: 21-May | AI1: 22-May | AJ1: 23-May | AK1: 24-May | AL1: 25-May | AM1: 26-May | AN1: 27-May | AO1: 28-May | AP1: 29-May | AQ1: 30-May | AR1: 31-May | AS1: 01-Jun | AT1: 02-Jun | AU1: 03-Jun | AV1: 04-Jun | AW1: 05-Jun | AX1: 06-Jun | AY1: 07-Jun | AZ1: 08-Jun | BA1: 09-Jun | BB1: 10-Jun | BC1: 11-Jun | BD1: 12-Jun | BE1: 13-Jun | BF1: 14-Jun | BG1: 15-Jun | BH1: 16-Jun | BI1: 17-Jun | BJ1: 18-Jun | BK1: 19-Jun | BL1: 20-Jun | BM1: 21-Jun | BN1: 22-Jun | BO1: 23-Jun | BP1: 24-Jun | BQ1: 25-Jun | BR1: 26-Jun | BS1: 27-Jun | BT1: 28-Jun | BU1: 29-Jun | BV1: 30-Jun | BW1: 01-Jul | BX1: 02-Jul | BY1: 03-Jul | BZ1: 04-Jul | CA1: 05-Jul | CB1: 06-Jul | CC1: 07-Jul | CD1: 08-Jul | CE1: 09-Jul | CF1: 10-Jul | CG1: 11-Jul | CH1: 12-Jul | CI1: 13-Jul | CJ1: 14-Jul | CK1: 15-Jul | CL1: 16-Jul | CM1: 17-Jul | CN1: 18-Jul | CO1: 19-Jul | CP1: 20-Jul | CQ1: 21-Jul | CR1: 22-Jul | CS1: 23-Jul | CT1: 24-Jul | CU1: 25-Jul | CV1: 26-Jul | CW1: 27-Jul | CX1: 28-Jul | CY1: 29-Jul | CZ1: 30-Jul | DA1: 31-Jul | DB1: 01-Aug | DC1: 02-Aug | DD1: 03-Aug | DE1: 04-Aug | DF1: 05-Aug | DG1: 06-Aug | DH1: 07-Aug | DI1: 08-Aug | DJ1: 09-Aug | DK1: 10-Aug | DL1: 11-Aug | DM1: 12-Aug | DN1: 13-Aug | DO1: 14-Aug | DP1: 15-Aug | DQ1: 16-Aug | DR1: 17-Aug | DS1: 18-Aug | DT1: 19-Aug | DU1: 20-Aug | DV1: 21-Aug | DW1: 22-Aug | DX1: 23-Aug | DY1: 24-Aug | DZ1: 25-Aug | EA1: 26-Aug | EB1: 27-Aug | EC1: 28-Aug | ED1: 29-Aug | EE1: 30-Aug | EF1: 31-Aug | EG1: 01-Sep | EH1: 02-Sep | EI1: 03-Sep | EJ1: 04-Sep | EK1: 05-Sep | EL1: 06-Sep | EM1: 07-Sep | EN1: 08-Sep | EO1: 09-Sep | EP1: 10-Sep | EQ1: 11-Sep | ER1: 12-Sep | ES1: 13-Sep | ET1: 14-Sep | EU1: 15-Sep | EV1: 16-Sep | EW1: 17-Sep | EX1: 18-Sep | EY1: 19-Sep | EZ1: 20-Sep | FA1: 21-Sep | FB1: 22-Sep | FC1: 23-Sep | FD1: 24-Sep | FE1: 25-Sep | FF1: 26-Sep | FG1: 27-Sep | FH1: 28-Sep | FI1: 29-Sep | FJ1: 30-Sep | FK1: 01-Oct | FL1: 02-Oct | FM1: 03-Oct | FN1: 04-Oct | FO1: 05-Oct | FP1: 06-Oct | FQ1: 07-Oct | FR1: 08-Oct | FS1: 09-Oct | FT1: 10-Oct | FU1: 11-Oct | FV1: 12-Oct | FW1: 13-Oct | FX1: 14-Oct | FY1: 15-Oct | FZ1: 16-Oct | GA1: 17-Oct | GB1: 18-Oct | GC1: 19-Oct | GD1: 20-Oct | GE1: 21-Oct | GF1: 22-Oct | GG1: 23-Oct | GH1: 24-Oct | GI1: 25-Oct | GJ1: 26-Oct | GK1: 27-Oct | GL1: 28-Oct | GM1: 29-Oct | GN1: 30-Oct | GO1: 31-Oct | GP1: 01-Nov | GQ1: 02-Nov | GR1: 03-Nov | GS1: 04-Nov | GT1: 05-Nov | GU1: 06-Nov | GV1: 07-Nov | GW1: 08-Nov | GX1: 09-Nov | GY1: 10-Nov | GZ1: 11-Nov | HA1: 12-Nov | HB1: 13-Nov | HC1: 14-Nov | HD1: 15-Nov | HE1: 16-Nov | HF1: 17-Nov | HG1: 18-Nov | HH1: 19-Nov | HI1: 20-Nov | HJ1: 21-Nov | HK1: 22-Nov | HL1: 23-Nov | HM1: 24-Nov | HN1: 25-Nov | HO1: 26-Nov | HP1: 27-Nov | HQ1: 28-Nov | HR1: 29-Nov | HS1: 30-Nov | HT1: 01-Dec | HU1: 02-Dec | HV1: 03-Dec | HW1: 04-Dec | HX1: 05-Dec | HY1: 06-Dec | HZ1: 07-Dec | IA1: 08-Dec | IB1: 09-Dec | IC1: 10-Dec | ID1: 11-Dec | IE1: 12-Dec | IF1: 13-Dec | IG1: 14-Dec | IH1: 15-Dec | II1: 16-Dec | IJ1: 17-Dec | IK1: 18-Dec | IL1: 19-Dec | IM1: 20-Dec | IN1: 21-Dec | IO1: 22-Dec | IP1: 23-Dec | IQ1: 24-Dec | IR1: 25-Dec | IS1: 26-Dec | IT1: 27-Dec | IU1: 28-Dec | IV1: 29-Dec | IW1: 30-Dec | IX1: 31-Dec
A2: IOB-002 | B2: WARMING BLANKET | C2: INTRAOPERATIVE | D2: LOWER BODY | E2: ="Intraoperative Warming Blanket Lower Body 62"" x 46"" (142 cm x 120 cm)"&CHAR(10)&"LOT # "&H2&" "&"EXP # "&TEXT(I2,"dd-mm-yyyy") -> Intraoperative Warming Blanket Lower Body 62" x 46" (142 cm x 120 cm) LOT # WB250608002S EXP # 07-06-2028 | F2: IOB | G2: OUT OF STOCK | H2: WB250608002S | I2: 46911 | J2: =K2-L2 -> 0 | K2: 0 | L2: =SUM(N2:IX2) -> 0 | M2: B
A3: IOB-002 | B3: WARMING BLANKET | C3: INTRAOPERATIVE | D3: LOWER BODY | E3: ="Intraoperative Warming Blanket Lower Body 62"" x 46"" (142 cm x 120 cm)"&CHAR(10)&"LOT # "&H3&" "&"EXP # "&TEXT(I3,"dd-mm-yyyy") -> Intraoperative Warming Blanket Lower Body 62" x 46" (142 cm x 120 cm) LOT # 25082702002 EXP # 26-08-2028 | F3: IOB | G3: OUT OF STOCK | H3: 25082702002 | I3: 46991 | J3: =K3-L3 -> 0 | K3: 0 | L3: =SUM(N3:IX3) -> 0 | M3: B
A4: IOB-002 | B4: WARMING BLANKET | C4: INTRAOPERATIVE | D4: LOWER BODY | E4: ="Intraoperative Warming Blanket Lower Body 62"" x 46"" (142 cm x 120 cm)"&CHAR(10)&"LOT # "&H4&" "&"EXP # "&TEXT(I4,"dd-mm-yyyy") -> Intraoperative Warming Blanket Lower Body 62" x 46" (142 cm x 120 cm) LOT # 25121206002 EXP # 11-12-2028 | F4: IOB | G4: NEAR EXP | H4: 25121206002 | I4: 47098 | J4: =K4-L4 -> 24 | K4: 99 | L4: =SUM(N4:IX4) -> 75 | M4: B | R4: =40 -> 40 | Y4: =20 -> 20 | AH4: =15 -> 15
A5: IOB-002 | B5: WARMING BLANKET | C5: INTRAOPERATIVE | D5: LOWER BODY | E5: ="Intraoperative Warming Blanket Lower Body 62"" x 46"" (142 cm x 120 cm)"&CHAR(10)&"LOT # "&H5&" "&"EXP # "&TEXT(I5,"dd-mm-yyyy") -> Intraoperative Warming Blanket Lower Body 62" x 46" (142 cm x 120 cm) LOT # 25051203002 EXP # 11-05-2028 | F5: IOB | G5: OUT OF STOCK | H5: 25051203002 | I5: 46884 | J5: =K5-L5 -> 0 | K5: 0 | L5: =SUM(N5:IX5) -> 0 | M5: B
A6: IOB-002 | B6: WARMING BLANKET | C6: INTRAOPERATIVE | D6: LOWER BODY | E6: ="Intraoperative Warming Blanket Lower Body 62"" x 46"" (142 cm x 120 cm)"&CHAR(10)&"LOT # "&H6&" "&"EXP # "&TEXT(I6,"dd-mm-yyyy") -> Intraoperative Warming Blanket Lower Body 62" x 46" (142 cm x 120 cm) LOT # WB230714002S EXP # 13-07-2026 | F6: IOB | G6: OUT OF STOCK | H6: WB230714002S | I6: 46216 | J6: =K6-L6 -> 0 | K6: 0 | L6: =SUM(N6:IX6) -> 0 | M6: =SUM(J2:J6) -> 24
A7: IOB-003 | B7: WARMING BLANKET | C7: INTRAOPERATIVE | D7: UPPER BODY | E7: ="Intraoperative Warming Blanket Upper Body 80"" x 25"" (202 cm x 64 cm)"&CHAR(10)&"LOT # "&H7&" "&"EXP # "&TEXT(I7,"dd-mm-yyyy") -> Intraoperative Warming Blanket Upper Body 80" x 25" (202 cm x 64 cm) LOT # 25072302003 EXP # 22-07-2028 | F7: IOB | G7: OUT OF STOCK | H7: 25072302003 | I7: 46956 | J7: =K7-L7 -> 0 | K7: 0 | L7: =SUM(N7:IX7) -> 0 | M7: B
A8: IOB-003 | E8: ="Intraoperative Warming Blanket Upper Body 80"" x 25"" (202 cm x 64 cm)"&CHAR(10)&"LOT # "&H8&" "&"EXP # "&TEXT(I8,"dd-mm-yyyy") -> Intraoperative Warming Blanket Upper Body 80" x 25" (202 cm x 64 cm) LOT # 25121901003 EXP # 18-12-2028 | F8: IOB | G8: OUT OF STOCK | H8: 25121901003 | I8: 47105 | J8: =K8-L8 -> 0 | K8: 0 | L8: =SUM(N8:IX8) -> 0 | M8: B
A9: IOB-003 | B9: WARMING BLANKET | C9: INTRAOPERATIVE | D9: UPPER BODY | E9: ="Intraoperative Warming Blanket Upper Body 80"" x 25"" (202 cm x 64 cm)"&CHAR(10)&"LOT # "&H9&" "&"EXP # "&TEXT(I9,"dd-mm-yyyy") -> Intraoperative Warming Blanket Upper Body 80" x 25" (202 cm x 64 cm) LOT # WB250607003S EXP # 06-06-2028 | F9: IOB | G9: OUT OF STOCK | H9: WB250607003S | I9: 46910 | J9: =K9-L9 -> 0 | K9: 0 | L9: =SUM(N9:IX9) -> 0 | M9: B
A10: IOB-003 | B10: WARMING BLANKET | C10: INTRAOPERATIVE | D10: UPPER BODY | E10: ="Intraoperative Warming Blanket Upper Body 80"" x 25"" (202 cm x 64 cm)"&CHAR(10)&"LOT # "&H10&" "&"EXP # "&TEXT(I10,"dd-mm-yyyy") -> Intraoperative Warming Blanket Upper Body 80" x 25" (202 cm x 64 cm) LOT # WB230720003S EXP # 19-07-2026 | F10: IOB | G10: OUT OF STOCK | H10: WB230720003S | I10: 46222 | J10: =K10-L10 -> 0 | K10: 0 | L10: =SUM(N10:IX10) -> 0 | M10: B
A11: IOB-003 | E11: ="Intraoperative Warming Blanket Upper Body 80"" x 25"" (202 cm x 64 cm)"&CHAR(10)&"LOT # "&H11&" "&"EXP # "&TEXT(I11,"dd-mm-yyyy") -> Intraoperative Warming Blanket Upper Body 80" x 25" (202 cm x 64 cm) LOT # 26030601003 EXP # 05-03-2029 | F11: IOB | G11: NEAR EXP | H11: 26030601003 | I11: 47182 | J11: =K11-L11 -> 767 | K11: 1400 | L11: =SUM(N11:IX11) -> 633 | M11: B | V11: =20+40+50+20+40+40+50+73+110 -> 443 | AF11: =60 -> 60 | AH11: =40 -> 40 | AS11: =50+40 -> 90
A12: IOB-003 | B12: WARMING BLANKET | C12: INTRAOPERATIVE | D12: UPPER BODY | E12: ="Intraoperative Warming Blanket Upper Body 80"" x 25"" (202 cm x 64 cm)"&CHAR(10)&"LOT # "&H12&" "&"EXP # "&TEXT(I12,"dd-mm-yyyy") -> Intraoperative Warming Blanket Upper Body 80" x 25" (202 cm x 64 cm) LOT # WB230615003 EXP # 14-06-2026 | F12: IOB | G12: OUT OF STOCK | H12: WB230615003 | I12: 46187 | J12: =K12-L12 -> 0 | K12: 0 | L12: =SUM(N12:IX12) -> 0 | M12: B
A13: IOB-003 | B13: WARMING BLANKET | C13: INTRAOPERATIVE | D13: UPPER BODY | E13: ="Intraoperative Warming Blanket Upper Body 80"" x 25"" (202 cm x 64 cm)"&CHAR(10)&"LOT # "&H13&" "&"EXP # "&TEXT(I13,"dd-mm-yyyy") -> Intraoperative Warming Blanket Upper Body 80" x 25" (202 cm x 64 cm) LOT # 25030501003 EXP # 04-03-2028 | F13: IOB | G13: OUT OF STOCK | H13: 25030501003 | I13: 46816 | J13: =K13-L13 -> 0 | K13: 0 | L13: =SUM(N13:IX13) -> 0 | M13: =SUM(J7:J13) -> 767
A14: IOB-004 | B14: WARMING BLANKET | C14: INTRAOPERATIVE | D14: FULL BODY | E14: ="Intraoperative Warming Blanket Adult Full Body 83"" x 47"" (210 cm x 120 cm) 40/box"&CHAR(10)&"LOT # "&H14&" "&"EXP # "&TEXT(I14,"dd-mm-yyyy") -> Intraoperative Warming Blanket Adult Full Body 83" x 47" (210 cm x 120 cm) 40/box LOT # 25072104004 EXP # 20-07-2028 | F14: IOB | G14: OUT OF STOCK | H14: 25072104004 | I14: 46954 | J14: =K14-L14 -> 0 | K14: 0 | L14: =SUM(N14:IX14) -> 0 | M14: B
A15: IOB-004 | B15: WARMING BLANKET | C15: INTRAOPERATIVE | D15: FULL BODY | E15: ="Intraoperative Warming Blanket Adult Full Body 83"" x 47"" (210 cm x 120 cm) 40/box"&CHAR(10)&"LOT # "&H15&" "&"EXP # "&TEXT(I15,"dd-mm-yyyy") -> Intraoperative Warming Blanket Adult Full Body 83" x 47" (210 cm x 120 cm) 40/box LOT # 25030502004 EXP # 04-03-2028 | F15: IOB | G15: OUT OF STOCK | H15: 25030502004 | I15: 46816 | J15: =K15-L15 -> 0 | K15: 0 | L15: =SUM(N15:IX15) -> 0 | M15: B
A16: IOB-004 | E16: ="Intraoperative Warming Blanket Adult Full Body 83"" x 47"" (210 cm x 120 cm) 40/box"&CHAR(10)&"LOT # "&H16&" "&"EXP # "&TEXT(I16,"dd-mm-yyyy") -> Intraoperative Warming Blanket Adult Full Body 83" x 47" (210 cm x 120 cm) 40/box LOT # 25121903004 EXP # 18-12-2028 | F16: IOB | G16: OUT OF STOCK | H16: 25121903004 | I16: 47105 | J16: =K16-L16 -> 0 | K16: 208 | L16: =SUM(N16:IX16) -> 208 | M16: B | N16: =5+2+10 -> 17 | R16: =80 -> 80 | S16: =40 -> 40 | U16: =40 -> 40 | Y16: =20 -> 20 | AA16: =11 -> 11
A17: IOB-004 | E17: ="Intraoperative Warming Blanket Adult Full Body 83"" x 47"" (210 cm x 120 cm) 40/box"&CHAR(10)&"LOT # "&H17&" "&"EXP # "&TEXT(I17,"dd-mm-yyyy") -> Intraoperative Warming Blanket Adult Full Body 83" x 47" (210 cm x 120 cm) 40/box LOT # 26032302004 EXP # 22-03-2029 | F17: IOB | G17: NEAR EXP | H17: 26032302004 | I17: 47199 | J17: =K17-L17 -> 6733 | K17: 11000 | L17: =SUM(N17:IX17) -> 4267 | M17: B | V17: =120+320+320+880+320+80 -> 2040 | AA17: =109 -> 109 | AE17: =30+320 -> 350 | AG17: =1000 -> 1000 | AK17: =120+40 -> 160 | AS17: =160+3+5+200 -> 368 | AT17: =120+120 -> 240
A18: IOB-004 | B18: WARMING BLANKET | C18: INTRAOPERATIVE | D18: FULL BODY | E18: ="Intraoperative Warming Blanket Adult Full Body 83"" x 47"" (210 cm x 120 cm) 40/box"&CHAR(10)&"LOT # "&H18&" "&"EXP # "&TEXT(I18,"dd-mm-yyyy") -> Intraoperative Warming Blanket Adult Full Body 83" x 47" (210 cm x 120 cm) 40/box LOT # 25082705004 EXP # 26-08-2028 | F18: IOB | G18: OUT OF STOCK | H18: 25082705004 | I18: 46991 | J18: =K18-L18 -> 0 | K18: 0 | L18: =SUM(N18:IX18) -> 0 | M18: B
A19: IOB-004 | B19: WARMING BLANKET | C19: INTRAOPERATIVE | D19: FULL BODY | E19: ="Intraoperative Warming Blanket Adult Full Body 83"" x 47"" (210 cm x 120 cm) 40/box"&CHAR(10)&"LOT # "&H19&" "&"EXP # "&TEXT(I19,"dd-mm-yyyy") -> Intraoperative Warming Blanket Adult Full Body 83" x 47" (210 cm x 120 cm) 40/box LOT # 25042302004 EXP # 22-04-2028 | F19: IOB | G19: OUT OF STOCK | H19: 25042302004 | I19: 46865 | J19: =K19-L19 -> 0 | K19: 0 | L19: =SUM(N19:IX19) -> 0 | M19: B
A20: IOB-004 | B20: WARMING BLANKET | C20: INTRAOPERATIVE | D20: FULL BODY | E20: ="Intraoperative Warming Blanket Adult Full Body 83"" x 47"" (210 cm x 120 cm) 40/box"&CHAR(10)&"LOT # "&H20&" "&"EXP # "&TEXT(I20,"dd-mm-yyyy") -> Intraoperative Warming Blanket Adult Full Body 83" x 47" (210 cm x 120 cm) 40/box LOT # 25030403004 EXP # 03-03-2028 | F20: IOB | G20: OUT OF STOCK | H20: 25030403004 | I20: 46815 | J20: =K20-L20 -> 0 | K20: 0 | L20: =SUM(N20:IX20) -> 0 | M20: =SUM(J14:J20) -> 6733
A21: IOB-006 | B21: WARMING BLANKET | C21: UNDER BODY | D21: UNDER BODY | E21: ="Underbody Warming Blanket Full Access Underbody 85"" x 47"" (210 cm x 120cm)"&CHAR(10)&"LOT # "&H21&" "&"EXP # "&TEXT(I21,"dd-mm-yyyy") -> Underbody Warming Blanket Full Access Underbody 85" x 47" (210 cm x 120cm) LOT # WB230612004 EXP # 10-06-2028 | F21: IOB | G21: NEAR EXP | H21: WB230612004 | I21: 46914 | J21: =K21-L21 -> 370 | K21: 370 | L21: =SUM(N21:IX21) -> 0 | M21: =SUM(J21) -> 370
A22: IOB-007 | B22: WARMING BLANKET | C22: PEDIATRIC | D22: FULL BODY | E22: ="Pediatric Warming Blanket Pediatric Full Body 67"" x 39"" (170cm x 100cm)"&CHAR(10)&"LOT # "&H22&" "&"EXP # "&TEXT(I22,"dd-mm-yyyy") -> Pediatric Warming Blanket Pediatric Full Body 67" x 39" (170cm x 100cm) LOT # WB230715007S EXP # 14-07-2026 | F22: IOB | G22: OUT OF STOCK | H22: WB230715007S | I22: 46217 | J22: =K22-L22 -> 0 | K22: 0 | L22: =SUM(N22:IX22) -> 0 | M22: B
A23: IOB-007 | B23: WARMING BLANKET | C23: PEDIATRIC | D23: FULL BODY | E23: ="Pediatric Warming Blanket Pediatric Full Body 67"" x 39"" (170cm x 100cm)"&CHAR(10)&"LOT # "&H23&" "&"EXP # "&TEXT(I23,"dd-mm-yyyy") -> Pediatric Warming Blanket Pediatric Full Body 67" x 39" (170cm x 100cm) LOT # WB230617007S EXP # 16-06-2026 | F23: IOB | G23: OUT OF STOCK | H23: WB230617007S | I23: 46189 | J23: =K23-L23 -> 0 | K23: 0 | L23: =SUM(N23:IX23) -> 0 | M23: B
A24: IOB-007 | B24: WARMING BLANKET | C24: PEDIATRIC | D24: FULL BODY | E24: ="Pediatric Warming Blanket Pediatric Full Body 67"" x 39"" (170cm x 100cm)"&CHAR(10)&"LOT # "&H24&" "&"EXP # "&TEXT(I24,"dd-mm-yyyy") -> Pediatric Warming Blanket Pediatric Full Body 67" x 39" (170cm x 100cm) LOT # 25111702007 EXP # 16-11-2028 | F24: IOB | G24: OUT OF STOCK | H24: 25111702007 | I24: 47073 | J24: =K24-L24 -> 0 | K24: 0 | L24: =SUM(N24:IX24) -> 0 | M24: B
A25: IOB-007 | B25: WARMING BLANKET | C25: PEDIATRIC | D25: FULL BODY | E25: ="Pediatric Warming Blanket Pediatric Full Body 67"" x 39"" (170cm x 100cm)"&CHAR(10)&"LOT # "&H25&" "&"EXP # "&TEXT(I25,"dd-mm-yyyy") -> Pediatric Warming Blanket Pediatric Full Body 67" x 39" (170cm x 100cm) LOT # 25121104007 EXP # 10-12-2028 | F25: IOB | G25: NEAR EXP | H25: 25121104007 | I25: 47097 | J25: =K25-L25 -> 224 | K25: 384 | L25: =SUM(N25:IX25) -> 160 | M25: B | AE25: =120 -> 120 | AT25: =40 -> 40
A26: IOB-007 | B26: WARMING BLANKET | C26: PEDIATRIC | D26: FULL BODY | E26: ="Pediatric Warming Blanket Pediatric Full Body 67"" x 39"" (170cm x 100cm)"&CHAR(10)&"LOT # "&H26&" "&"EXP # "&TEXT(I26,"dd-mm-yyyy") -> Pediatric Warming Blanket Pediatric Full Body 67" x 39" (170cm x 100cm) LOT # WB230715007S EXP # 14-07-2026 | F26: IOB | G26: OUT OF STOCK | H26: WB230715007S | I26: 46217 | J26: =K26-L26 -> 0 | K26: 0 | L26: =SUM(N26:IX26) -> 0 | M26: B
A27: IOB-007 | B27: WARMING BLANKET | C27: PEDIATRIC | D27: FULL BODY | E27: ="Pediatric Warming Blanket Pediatric Full Body 67"" x 39"" (170cm x 100cm)"&CHAR(10)&"LOT # "&H27&" "&"EXP # "&TEXT(I27,"dd-mm-yyyy") -> Pediatric Warming Blanket Pediatric Full Body 67" x 39" (170cm x 100cm) LOT # 25030503007 EXP # 04-03-2028 | F27: IOB | G27: OUT OF STOCK | H27: 25030503007 | I27: 46816 | J27: =K27-L27 -> 0 | K27: 0 | L27: =SUM(N27:IX27) -> 0 | M27: =SUM(J22:J27) -> 224
A28: IOB-008 | B28: WARMING BLANKET | C28: POSTOPERATIVE - SURGICAL | D28: FULL BODY | E28: ="Postoperative Warming Blanket Full Body Surgical 83"" x 47"" (210cm X 120cm)"&CHAR(10)&"LOT # "&H28&" "&"EXP # "&TEXT(I28,"dd-mm-yyyy") -> Postoperative Warming Blanket Full Body Surgical 83" x 47" (210cm X 120cm) LOT # 25042801008 EXP # 27-04-2028 | F28: IOB | G28: OUT OF STOCK | H28: 25042801008 | I28: 46870 | J28: =K28-L28 -> 0 | K28: 0 | L28: =SUM(N28:IX28) -> 0 | M28: B
A29: IOB-008 | B29: WARMING BLANKET | C29: POSTOPERATIVE - SURGICAL | D29: FULL BODY | E29: ="Postoperative Warming Blanket Full Body Surgical 83"" x 47"" (210cm X 120cm)"&CHAR(10)&"LOT # "&H29&" "&"EXP # "&TEXT(I29,"dd-mm-yyyy") -> Postoperative Warming Blanket Full Body Surgical 83" x 47" (210cm X 120cm) LOT # 25082701008 EXP # 26-08-2028 | F29: IOB | G29: NEAR EXP | H29: 25082701008 | I29: 46991 | J29: =K29-L29 -> 420 | K29: 500 | L29: =SUM(N29:IX29) -> 80 | M29: B | T29: =40 -> 40 | AS29: =40 -> 40
A30: IOB-008 | B30: WARMING BLANKET | C30: POSTOPERATIVE - SURGICAL | D30: FULL BODY | E30: ="Postoperative Warming Blanket Full Body Surgical 83"" x 47"" (210cm X 120cm)"&CHAR(10)&"LOT # "&H30&" "&"EXP # "&TEXT(I30,"dd-mm-yyyy") -> Postoperative Warming Blanket Full Body Surgical 83" x 47" (210cm X 120cm) LOT # WB230717008S EXP # 16-07-2026 | F30: IOB | G30: OUT OF STOCK | H30: WB230717008S | I30: 46219 | J30: =K30-L30 -> 0 | K30: 0 | L30: =SUM(N30:IX30) -> 0 | M30: =SUM(J28:J30) -> 420
A31: IOB-009 | B31: WARMING BLANKET | C31: LARGE PEDIATRIC | D31: UNDER BODY | E31: ="Large Pediatric Under Body 36"" x 31""(160cm x 80cm)"&CHAR(10)&"LOT # "&H31&" "&"EXP # "&TEXT(I31,"dd-mm-yyyy") -> Large Pediatric Under Body 36" x 31"(160cm x 80cm) LOT # 25082706009 EXP # 26-08-2028 | F31: IOB | G31: NEAR EXP | H31: 25082706009 | I31: 46991 | J31: =K31-L31 -> 390 | K31: 390 | L31: =SUM(N31:IX31) -> 0 | M31: B
A32: IOB-009 | B32: WARMING BLANKET | C32: LARGE PEDIATRIC | D32: UNDER BODY | E32: ="Large Pediatric Under Body 36"" x 31""(160cm x 80cm)"&CHAR(10)&"LOT # "&H32&" "&"EXP # "&TEXT(I32,"dd-mm-yyyy") -> Large Pediatric Under Body 36" x 31"(160cm x 80cm) LOT # WB202406200 EXP # 19-06-2027 | F32: IOB | G32: OUT OF STOCK | H32: WB202406200 | I32: 46557 | J32: =K32-L32 -> 0 | K32: 0 | L32: =SUM(N32:IX32) -> 0 | M32: =SUM(J31:J32) -> 390
A33: IOB-012 | B33: WARMING BLANKET | C33: PEDIATRIC | D33: LOWER BODY | E33: ="Pediatric Warming Blanket Pediatric Lower Body 56"" x 39""(142cm x 100cm)"&CHAR(10)&"LOT # "&H33&" "&"EXP # "&TEXT(I33,"dd-mm-yyyy") -> Pediatric Warming Blanket Pediatric Lower Body 56" x 39"(142cm x 100cm) LOT # 20240120 EXP # 17-09-2027 | F33: IOB | G33: NEAR EXP | H33: 20240120 | I33: 46647 | J33: =K33-L33 -> 322 | K33: 322 | L33: =SUM(N33:IX33) -> 0 | M33: =SUM(J33) -> 322
A34: IOB-016 | B34: WARMING BLANKET | C34: SURGICAL | D34: SURGICAL | E34: ="Surgical Access Warming Blanket 83"" x 47"" (210cm x 120cm)"&CHAR(10)&"LOT # "&H34&" "&"EXP # "&TEXT(I34,"dd-mm-yyyy") -> Surgical Access Warming Blanket 83" x 47" (210cm x 120cm) LOT # WB240827016 EXP # 26-08-2027 | F34: IOB | G34: OUT OF STOCK | H34: WB240827016 | I34: 46625 | J34: =K34-L34 -> 0 | K34: 0 | L34: =SUM(N34:IX34) -> 0 | M34: B
A35: IOB-016 | B35: WARMING BLANKET | C35: SURGICAL | D35: SURGICAL | E35: ="Surgical Access Warming Blanket 83"" x 47"" (210cm x 120cm)"&CHAR(10)&"LOT # "&H35&" "&"EXP # "&TEXT(I35,"dd-mm-yyyy") -> Surgical Access Warming Blanket 83" x 47" (210cm x 120cm) LOT # 25072304016 EXP # 22-07-2028 | F35: IOB | G35: OUT OF STOCK | H35: 25072304016 | I35: 46956 | J35: =K35-L35 -> 0 | K35: 0 | L35: =SUM(N35:IX35) -> 0 | M35: B
A36: IOB-016 | B36: WARMING BLANKET | C36: SURGICAL | D36: SURGICAL | E36: ="Surgical Access Warming Blanket 83"" x 47"" (210cm x 120cm)"&CHAR(10)&"LOT # "&H36&" "&"EXP # "&TEXT(I36,"dd-mm-yyyy") -> Surgical Access Warming Blanket 83" x 47" (210cm x 120cm) LOT # 25121902016 EXP # 18-12-2028 | F36: IOB | G36: OUT OF STOCK | H36: 25121902016 | I36: 47105 | J36: =K36-L36 -> 0 | K36: 0 | L36: =SUM(N36:IX36) -> 0 | M36: B
A37: IOB-016 | B37: WARMING BLANKET | C37: SURGICAL | D37: SURGICAL | E37: ="Surgical Access Warming Blanket 83"" x 47"" (210cm x 120cm)"&CHAR(10)&"LOT # "&H37&" "&"EXP # "&TEXT(I37,"dd-mm-yyyy") -> Surgical Access Warming Blanket 83" x 47" (210cm x 120cm) LOT # 25092201016 EXP # 21-09-2028 | F37: IOB | G37: NEAR EXP | H37: 25092201016 | I37: 47017 | J37: =K37-L37 -> 79 | K37: 239 | L37: =SUM(N37:IX37) -> 160 | M37: B | N37: =40+20 -> 60 | AH37: =40 -> 40 | AI37: =40 -> 40 | AS37: =20 -> 20
A38: IOB-016 | B38: WARMING BLANKET | C38: SURGICAL | D38: SURGICAL | E38: ="Surgical Access Warming Blanket 83"" x 47"" (210cm x 120cm)"&CHAR(10)&"LOT # "&H38&" "&"EXP # "&TEXT(I38,"dd-mm-yyyy") -> Surgical Access Warming Blanket 83" x 47" (210cm x 120cm) LOT # 25030504016 EXP # 04-03-2028 | F38: IOB | G38: OUT OF STOCK | H38: 25030504016 | I38: 46816 | J38: =K38-L38 -> 0 | K38: 0 | L38: =SUM(N38:IX38) -> 0 | M38: =SUM(J34:J38) -> 79
A39: IOB-025 | B39: WARMING BLANKET | C39: INFANT | D39: FULL BODY / UNDER BODY | E39: ="Infant Full Body / Under Body 47"" x 31"" (120cm x 80 cm)"&CHAR(10)&"LOT # "&H39&" "&"EXP # "&TEXT(I39,"dd-mm-yyyy") -> Infant Full Body / Under Body 47" x 31" (120cm x 80 cm) LOT # WU240737015 EXP # 15-03-2027 | F39: IOB | G39: NEAR EXP | H39: WU240737015 | I39: 46461 | J39: =K39-L39 -> 1 | K39: 1 | L39: =SUM(N39:IX39) -> 0 | M39: B
A40: IOB-025 | B40: WARMING BLANKET | C40: INFANT | D40: FULL BODY / UNDER BODY | E40: ="Infant Full Body / Under Body 47"" x 31"" (120cm x 80 cm)"&CHAR(10)&"LOT # "&H40&" "&"EXP # "&TEXT(I40,"dd-mm-yyyy") -> Infant Full Body / Under Body 47" x 31" (120cm x 80 cm) LOT # WU240737015 EXP # 15-03-2027 | F40: IOB | G40: EXPIRED | H40: WU240737015 | I40: 46461 | J40: =K40-L40 -> 464 | K40: 464 | L40: =SUM(N40:IX40) -> 0 | M40: =SUM(J39:J40) -> 465
...

Sheet SAMPLES 2026
A1: ITEM CODE | B1: ITEM NAME | C1: TYPE | D1: BODY PART | E1: DESCRIPTION | F1: MANUFACTURER | G1: STATUS | H1: LOT NO. | I1: EXP. DATE | J1: REMAINING QTY | K1: INPUT QTY | L1: OUT | M1: TOTAL | N1: 01-May | O1: 02-May | P1: 03-May | Q1: 04-May | R1: 05-May | S1: 06-May | T1: 07-May | U1: 08-May | V1: 09-May | W1: 10-May | X1: 11-May | Y1: 12-May | Z1: 13-May | AA1: 14-May | AB1: 15-May | AC1: 16-May | AD1: 17-May | AE1: 18-May | AF1: 19-May | AG1: 20-May | AH1: 21-May | AI1: 22-May | AJ1: 23-May | AK1: 24-May | AL1: 25-May | AM1: 26-May | AN1: 27-May | AO1: 28-May | AP1: 29-May | AQ1: 30-May | AR1: 31-May | AS1: 01-Jun | AT1: 02-Jun | AU1: 03-Jun | AV1: 04-Jun | AW1: 05-Jun | AX1: 06-Jun | AY1: 07-Jun | AZ1: 08-Jun | BA1: 09-Jun | BB1: 10-Jun | BC1: 11-Jun | BD1: 12-Jun | BE1: 13-Jun | BF1: 14-Jun | BG1: 15-Jun | BH1: 16-Jun | BI1: 17-Jun | BJ1: 18-Jun | BK1: 19-Jun | BL1: 20-Jun | BM1: 21-Jun | BN1: 22-Jun | BO1: 23-Jun | BP1: 24-Jun | BQ1: 25-Jun | BR1: 26-Jun | BS1: 27-Jun | BT1: 28-Jun | BU1: 29-Jun | BV1: 30-Jun | BW1: 01-Jul | BX1: 02-Jul | BY1: 03-Jul | BZ1: 04-Jul | CA1: 05-Jul | CB1: 06-Jul | CC1: 07-Jul | CD1: 08-Jul | CE1: 09-Jul | CF1: 10-Jul | CG1: 11-Jul | CH1: 12-Jul | CI1: 13-Jul | CJ1: 14-Jul | CK1: 15-Jul | CL1: 16-Jul | CM1: 17-Jul | CN1: 18-Jul | CO1: 19-Jul | CP1: 20-Jul | CQ1: 21-Jul | CR1: 22-Jul | CS1: 23-Jul | CT1: 24-Jul | CU1: 25-Jul | CV1: 26-Jul | CW1: 27-Jul | CX1: 28-Jul | CY1: 29-Jul | CZ1: 30-Jul | DA1: 31-Jul | DB1: 01-Aug | DC1: 02-Aug | DD1: 03-Aug | DE1: 04-Aug | DF1: 05-Aug | DG1: 06-Aug | DH1: 07-Aug | DI1: 08-Aug | DJ1: 09-Aug | DK1: 10-Aug | DL1: 11-Aug | DM1: 12-Aug | DN1: 13-Aug | DO1: 14-Aug | DP1: 15-Aug | DQ1: 16-Aug | DR1: 17-Aug | DS1: 18-Aug | DT1: 19-Aug | DU1: 20-Aug | DV1: 21-Aug | DW1: 22-Aug | DX1: 23-Aug | DY1: 24-Aug | DZ1: 25-Aug | EA1: 26-Aug | EB1: 27-Aug | EC1: 28-Aug | ED1: 29-Aug | EE1: 30-Aug | EF1: 31-Aug | EG1: 01-Sep | EH1: 02-Sep | EI1: 03-Sep | EJ1: 04-Sep | EK1: 05-Sep | EL1: 06-Sep | EM1: 07-Sep | EN1: 08-Sep | EO1: 09-Sep | EP1: 10-Sep | EQ1: 11-Sep | ER1: 12-Sep | ES1: 13-Sep | ET1: 14-Sep | EU1: 15-Sep | EV1: 16-Sep | EW1: 17-Sep | EX1: 18-Sep | EY1: 19-Sep | EZ1: 20-Sep | FA1: 21-Sep | FB1: 22-Sep | FC1: 23-Sep | FD1: 24-Sep | FE1: 25-Sep | FF1: 26-Sep | FG1: 27-Sep | FH1: 28-Sep | FI1: 29-Sep | FJ1: 30-Sep | FK1: 01-Oct | FL1: 02-Oct | FM1: 03-Oct | FN1: 04-Oct | FO1: 05-Oct | FP1: 06-Oct | FQ1: 07-Oct | FR1: 08-Oct | FS1: 09-Oct | FT1: 10-Oct | FU1: 11-Oct | FV1: 12-Oct | FW1: 13-Oct | FX1: 14-Oct | FY1: 15-Oct | FZ1: 16-Oct | GA1: 17-Oct | GB1: 18-Oct | GC1: 19-Oct | GD1: 20-Oct | GE1: 21-Oct | GF1: 22-Oct | GG1: 23-Oct | GH1: 24-Oct | GI1: 25-Oct | GJ1: 26-Oct | GK1: 27-Oct | GL1: 28-Oct | GM1: 29-Oct | GN1: 30-Oct | GO1: 31-Oct | GP1: 01-Nov | GQ1: 02-Nov | GR1: 03-Nov | GS1: 04-Nov | GT1: 05-Nov | GU1: 06-Nov | GV1: 07-Nov | GW1: 08-Nov | GX1: 09-Nov | GY1: 10-Nov | GZ1: 11-Nov | HA1: 12-Nov | HB1: 13-Nov | HC1: 14-Nov | HD1: 15-Nov | HE1: 16-Nov | HF1: 17-Nov | HG1: 18-Nov | HH1: 19-Nov | HI1: 20-Nov | HJ1: 21-Nov | HK1: 22-Nov | HL1: 23-Nov | HM1: 24-Nov | HN1: 25-Nov | HO1: 26-Nov | HP1: 27-Nov | HQ1: 28-Nov | HR1: 29-Nov | HS1: 30-Nov | HT1: 01-Dec | HU1: 02-Dec | HV1: 03-Dec | HW1: 04-Dec | HX1: 05-Dec | HY1: 06-Dec | HZ1: 07-Dec | IA1: 08-Dec | IB1: 09-Dec | IC1: 10-Dec | ID1: 11-Dec | IE1: 12-Dec | IF1: 13-Dec | IG1: 14-Dec | IH1: 15-Dec | II1: 16-Dec | IJ1: 17-Dec | IK1: 18-Dec | IL1: 19-Dec | IM1: 20-Dec | IN1: 21-Dec | IO1: 22-Dec | IP1: 23-Dec | IQ1: 24-Dec | IR1: 25-Dec | IS1: 26-Dec | IT1: 27-Dec | IU1: 28-Dec | IV1: 29-Dec | IW1: 30-Dec | IX1: 31-Dec
A2: GSS2212 | B2: GAUZE SWAB | E2: Gauze Swab Sterile - 5x5-12Ply -13 Threads - Single Wrapped (5 Pcs/Pack, 20 Packs/Box,20Box/Ctn) | F2: JIUJANG HUADA | G2: NEAR EXP | H2: HD2303 | I2: 46813 | J2: =K2-L2 -> 5 | K2: 67 | L2: =SUM(N2:IX2) -> 62 | M2: B | S2: =12 -> 12 | AU2: =50 -> 50
A3: GSS2212 | B3: GAUZE SWAB | C3: M42 | E3: Gauze Swab Sterile - 5x5-12Ply -13 Threads - Double Wrapped (5 Pcs/Pack, 20 Packs/Box,20Box/Ctn) | F3: JIUJANG HUADA | G3: OUT OF STOCK | H3: HD202404 | I3: 47178 | J3: =K3-L3 -> 0 | K3: 0 | L3: =SUM(N3:IX3) -> 0 | M3: =SUM(J2:J3) -> 5
A4: GSS3312 | B4: GAUZE SWAB | C4: M42 | E4: Gauze Swab Sterile - 7.5x7.5-12Ply -13 Threads - Double Wrapped (5 Pcs/Pack, 20 Packs/Box,20Box/Ctn) | F4: JIUJANG HUADA | G4: NEAR EXP | H4: HD202404 | I4: 47178 | J4: =K4-L4 -> 2 | K4: 2 | L4: =SUM(N4:IX4) -> 0 | M4: =J4 -> 2
A5: GSS4412 | B5: GAUZE SWAB | E5: Gauze Swab Sterile - 10x10-12Ply -13 Threads - Single Wrapped (5 Pcs/Pack, 20 Packs/Box,24Box/Ctn) | F5: JIUJANG HUADA | G5: NEAR EXP | H5: HD2303 | I5: 46813 | J5: =K5-L5 -> 3 | K5: 63 | L5: =SUM(N5:IX5) -> 60 | M5: B | S5: =50 -> 50 | U5: =10 -> 10
A6: GSS4412 | B6: GAUZE SWAB | C6: M42 | E6: Gauze Swab Sterile - 10x10-12Ply -13 Threads - Double Wrapped (5 Pcs/Pack, 20 Packs/Box,24Box/Ctn) | F6: JIUJANG HUADA | G6: OUT OF STOCK | H6: HD202404 | I6: 47178 | J6: =K6-L6 -> 0 | K6: 0 | L6: =SUM(N6:IX6) -> 0 | M6: =SUM(J5:J6) -> 3
A7: GSS4412X | B7: GAUZE SWAB | C7: M42 | E7: Gauze Swab Sterile - 10x10-12Ply with X-Ray -13 Threads - Double Wrapped (5 Pcs/Pack, 20 Packs/Box,24Box/Ctn) | F7: jIUJANG HUADA | G7: OUT OF STOCK | H7: HD202404 | I7: 47178 | J7: =K7-L7 -> 0 | K7: 0 | L7: =SUM(N7:IX7) -> 0 | M7: =J7 -> 0
A8: GSS4416X | B8: GAUZE SWAB | E8: Gauze Swab Sterile - 10x10-16Ply with X-Ray -13 Threads - Double Wrapped (5 Pcs/Pack, 20 Packs/Box,24Box/Ctn) | F8: JIUJANG HUADA | G8: NEAR EXP | H8: HD202404 | I8: 47178 | J8: =K8-L8 -> 9 | K8: 9 | L8: =SUM(N8:IX8) -> 0 | M8: =J8 -> 9
A9: GSS4416X PACKS | B9: GAUZE SWAB | E9: Gauze Swab Sterile - 10x10-16Ply with X-Ray -13 Threads - Double Wrapped (PACKS) | F9: JIUJANG HUADA | G9: NEAR EXP | H9: HD202404 | I9: 47178 | J9: =K9-L9 -> 9 | K9: 9 | L9: =SUM(N9:IX9) -> 0 | M9: =J9 -> 9
A10: GS3312 | B10: GAUZE SWAB | C10: M42 | E10: Gauze Swab Non -Sterile - 7.5x7.5-12Ply -13 Threads (100 Pcs/Pack, 80 Packs/Ctn) | F10: JIUJANG HUADA | G10: OUT OF STOCK | H10: HD202404 | I10: 47178 | J10: =K10-L10 -> 0 | K10: 0 | L10: =SUM(N10:IX10) -> 0 | M10: =J10 -> 0
A11: GS2212 | B11: GAUZE SWAB | C11: M42 | E11: Gauze Swab Non -Sterile - 5x5-12Ply -13 Threads (100 Pcs/Pack, 100 Packs/Ctn) | F11: JIUJANG HUADA | G11: OUT OF STOCK | H11: HD2303 | I11: 46813 | J11: =K11-L11 -> 0 | K11: 0 | L11: =SUM(N11:IX11) -> 0 | M11: =J11 -> 0
A12: M-010604 | E12: Poviseptin Scrub Brush - 15ml - Nail Stick | F12: MEDITERA | G12: EXPIRED | H12: 6656-0308-13 | I12: 45872 | J12: =K12-L12 -> 38 | K12: 38 | L12: =SUM(N12:IX12) -> 0 | M12: =J12 -> 38
A13: YC.001 | E13: Ultrasound Gel 250 ML (Clear) | F13: TIANJIN | G13: EXPIRED | I13: 45294 | J13: =K13-L13 -> 25 | K13: 25 | L13: =SUM(N13:IX13) -> 0 | M13: B
A14: YC.001 | E14: Ultrasound Gel 250 ML (Clear) | F14: TIANJIN | G14: NEAR EXP | J14: =K14-L14 -> 3 | K14: 3 | L14: =SUM(N14:IX14) -> 0 | M14: B
A15: YC.001 | C15: M42 | E15: Ultrasound Gel 250 ML (Clear) | F15: TIANJIN | G15: NEAR EXP | H15: 2024021802 | I15: 46443 | J15: =K15-L15 -> 10 | K15: 10 | L15: =SUM(N15:IX15) -> 0 | M15: =SUM(J13:J15) -> 38
A16: YC.002 | E16: Ultrasound Gel 250 ML (Blue) | F16: TIANJIN | G16: EXPIRED | I16: 45294 | J16: =K16-L16 -> 8 | K16: 8 | L16: =SUM(N16:IX16) -> 0 | M16: =J16 -> 8
A17: CAKCDQ-118 | E17: DISPOSABLE STAPLE REMOVER | G17: NEAR EXP | H17: CDQ11823002 | I17: 46134 | J17: =K17-L17 -> 12 | K17: 12 | L17: =SUM(N17:IX17) -> 0 | M17: =J17 -> 12
A18: 6121XXL | E18: AG-Thigh Length,with Dotted silicone topband,Anti-Embolism Stocking (Pair)- XXL | F18: VARIMED | G18: OUT OF STOCK | H18: 0821-6908 | I18: 46235 | J18: =K18-L18 -> 0 | K18: 0 | L18: =SUM(N18:IX18) -> 0 | M18: =J18 -> 0
A19: 6121L | C19: M42 | E19: AG-Thigh Length,with Dotted silicone topband,Anti-Embolism Stocking (Pair)- L | F19: VARIMED | G19: NEAR EXP | H19: 0821-6906 | I19: 46235 | J19: =K19-L19 -> 0 | K19: 0 | L19: =SUM(N19:IX19) -> 0 | M19: B
A20: 6121L | C20: M42 | E20: AG-Thigh Length,with Dotted silicone topband,Anti-Embolism Stocking (Pair)- L | F20: VARIMED | G20: NEAR EXP | H20: 1223-7325 | I20: 47088 | J20: =K20-L20 -> 5 | K20: 5 | L20: =SUM(N20:IX20) -> 0 | M20: =SUM(J19:J20) -> 5
A21: 6121M | E21: AG-Thigh Length,with Dotted silicone topband,Anti-Embolism Stocking (Pair)- M | F21: VARIMED | G21: OUT OF STOCK | H21: 1023-7386 | I21: 47027 | J21: =K21-L21 -> 0 | K21: 0 | L21: =SUM(N21:IX21) -> 0 | M21: B
A22: 6121M | C22: M42 | E22: AG-Thigh Length,with Dotted silicone topband,Anti-Embolism Stocking (Pair)- M | F22: VARIMED | G22: OUT OF STOCK | H22: 0821-6905 | I22: 46235 | J22: =K22-L22 -> 0 | K22: 0 | L22: =SUM(N22:IX22) -> 0 | M22: =SUM(J21:J22) -> 0
A23: 6121S | C23: M42 | E23: AG-Thigh Length,with Dotted silicone topband,Anti-Embolism Stocking (Pair)- S | F23: VARIMED | G23: NEAR EXP | H23: 0522-7040 | I23: 46508 | J23: =K23-L23 -> 6 | K23: 6 | L23: =SUM(N23:IX23) -> 0 | M23: =J23 -> 6
A24: 6111XXL | C24: M42 | E24: AD - Knee Length, Anti-Embolism Stocking (Pair) - XXL | F24: VARIMED | G24: NEAR EXP | H24: 1023-7357 | I24: 47027 | J24: =K24-L24 -> 6 | K24: 6 | L24: =SUM(N24:IX24) -> 0 | M24: =J24 -> 6
A25: 6111XL | E25: AD - Knee Length, Anti-Embolism Stocking (Pair) - XL | F25: VARIMED | G25: NEAR EXP | H25: 1023-7356 | I25: 47027 | J25: =K25-L25 -> 2 | K25: 2 | L25: =SUM(N25:IX25) -> 0 | M25: B
A26: 6111XL | C26: M42 | E26: AD - Knee Length, Anti-Embolism Stocking (Pair) - XL | F26: VARIMED | G26: NEAR EXP | H26: 1023-7356 | I26: 47027 | J26: =K26-L26 -> 4 | K26: 4 | L26: =SUM(N26:IX26) -> 0 | M26: =SUM(J25:J26) -> 6
A27: 6111L | C27: M42 | E27: AD - Knee Length, Anti-Embolism Stocking (Pair) - L | F27: VARIMED | G27: NEAR EXP | H27: 0521-6861 | I27: 46143 | J27: =K27-L27 -> 5 | K27: 5 | L27: =SUM(N27:IX27) -> 0 | M27: B
A28: 6111L | E28: AD - Knee Length, Anti-Embolism Stocking (Pair) - L | F28: VARIMED | G28: NEAR EXP | H28: 0521-6861 | I28: 46143 | J28: =K28-L28 -> 3 | K28: 3 | L28: =SUM(N28:IX28) -> 0 | M28: =SUM(J27:J28) -> 8
A29: 6111M | C29: M42 | E29: AD - Knee Length, Anti-Embolism Stocking (Pair) - M | F29: VARIMED | G29: NEAR EXP | H29: 1023-7350 | I29: 47027 | J29: =K29-L29 -> 5 | K29: 5 | L29: =SUM(N29:IX29) -> 0 | M29: =SUM(J29) -> 5
A30: IOB-003 | E30: Intraoperative Warming Blanket Upper Body 80" x 25" (202 cm x 64 cm) | F30: IOB | G30: NEAR EXP | H30: WB230615003S | I30: 46187 | J30: =K30-L30 -> 20 | K30: 20 | L30: =SUM(N30:IX30) -> 0 | M30: B
A31: IOB-003 | E31: Intraoperative Warming Blanket Upper Body 80" x 25" (202 cm x 64 cm) | F31: IOB | G31: EXPIRED | H31: WB221228003S | I31: 46018 | J31: =K31-L31 -> 1 | K31: 1 | L31: =SUM(N31:IX31) -> 0 | M31: =SUM(J30:J31) -> 21
A32: IOB-028 | E32: Pediatric Warming Blanket Infant Under Body 39" x 39" (100cm X 100cm) 40/box | F32: IOB | G32: OUT OF STOCK | H32: WB220701028 | I32: 45838 | J32: =K32-L32 -> 0 | K32: 0 | L32: =SUM(N32:IX32) -> 0 | M32: =J32 -> 0
A33: IOB-025 | E33: Infant Full Body / Under Body 47" x 31 '(120cm x 80 cm) | F33: IOB | G33: EXPIRED | H33: 20220620 | I33: 45462 | J33: =K33-L33 -> 1 | K33: 1 | L33: =SUM(N33:IX33) -> 0 | M33: =J33 -> 1
A34: IOB-002S | E34: Intraoperative Warming Blanket Lower Body 62" x 46" (142 cm x 120 cm) | F34: IOB | G34: EXPIRED | H34: WB211025002S | I34: 45589 | J34: =K34-L34 -> 1 | K34: 1 | L34: =SUM(N34:IX34) -> 0 | M34: =J34 -> 1
A35: IOB-016 | E35: Surgical Access Warming Blanket 83" x 47" (210cm x 120cm) | F35: IOB | G35: NEAR EXP | H35: WB240827016 | I35: 46625 | J35: =K35-L35 -> 1 | K35: 1 | L35: =SUM(N35:IX35) -> 0 | M35: =J35 -> 1
A36: IOB-007S | E36: Pediatric Warming Blanket Pediatric Full Body 67" x 39" (170cm x 100cm) | F36: IOB | G36: EXPIRED | H36: WB221011007S | I36: 45940 | J36: =K36-L36 -> 2 | K36: 2 | L36: =SUM(N36:IX36) -> 0 | M36: B
A37: IOB-007S | E37: Pediatric Warming Blanket Pediatric Full Body 67" x 39" (170cm x 100cm) | F37: IOB | G37: OUT OF STOCK | H37: WB230617007S | I37: 46189 | J37: =K37-L37 -> 0 | K37: 0 | L37: =SUM(N37:IX37) -> 0 | M37: =SUM(J36:J37) -> 2
A38: LBTK-500-L | E38: LEG GARMENT COMPRESSION SLEEVES - LARGE | F38: LABTEK | G38: NEAR EXP | H38: 250615 | I38: 46905 | J38: =K38-L38 -> 4 | K38: 4 | L38: =SUM(N38:IX38) -> 0 | M38: =J38 -> 4
A39: LBTK-500-M | E39: LEG GARMENT COMPRESSION SLEEVES - MEDIUM | F39: LABTEK | G39: NEAR EXP | H39: 250615 | I39: 46905 | J39: =K39-L39 -> 3 | K39: 3 | L39: =SUM(N39:IX39) -> 0 | M39: =J39 -> 3
A40: LBTK-500-S | E40: LEG GARMENT COMPRESSION SLEEVES - SMALL | F40: LABTEK | G40: NEAR EXP | H40: 250615 | I40: 46905 | J40: =K40-L40 -> 4 | K40: 4 | L40: =SUM(N40:IX40) -> 0 | M40: =J40 -> 4
...

Sheet MACHINE AND SPARE PARTS 2026
A1: ITEM CODE | B1: ITEM NAME | C1: TYPE | D1: BODY PART | E1: DESCRIPTION | F1: MANUFACTURER | G1: STATUS | H1: LOT NO. / SN | I1: LOCATION | J1: EXP./ MANU. DATE | K1: REM QTY | L1: INPUT QTY | M1: OUT | N1: TOTAL | O1: 01-May | P1: 02-May | Q1: 03-May | R1: 04-May | S1: 05-May | T1: 06-May | U1: 07-May | V1: 08-May | W1: 09-May | X1: 10-May | Y1: 11-May | Z1: 12-May | AA1: 13-May | AB1: 14-May | AC1: 15-May | AD1: 16-May | AE1: 17-May | AF1: 18-May | AG1: 19-May | AH1: 20-May | AI1: 21-May | AJ1: 22-May | AK1: 23-May | AL1: 24-May | AM1: 25-May | AN1: 26-May | AO1: 27-May | AP1: 28-May | AQ1: 29-May | AR1: 30-May | AS1: 31-May | AT1: 01-Jun | AU1: 02-Jun | AV1: 03-Jun | AW1: 04-Jun | AX1: 05-Jun | AY1: 06-Jun | AZ1: 07-Jun | BA1: 08-Jun | BB1: 09-Jun | BC1: 10-Jun | BD1: 11-Jun | BE1: 12-Jun | BF1: 13-Jun | BG1: 14-Jun | BH1: 15-Jun | BI1: 16-Jun | BJ1: 17-Jun | BK1: 18-Jun | BL1: 19-Jun | BM1: 20-Jun | BN1: 21-Jun | BO1: 22-Jun | BP1: 23-Jun | BQ1: 24-Jun | BR1: 25-Jun | BS1: 26-Jun | BT1: 27-Jun | BU1: 28-Jun | BV1: 29-Jun | BW1: 30-Jun | BX1: 01-Jul | BY1: 02-Jul | BZ1: 03-Jul | CA1: 04-Jul | CB1: 05-Jul | CC1: 06-Jul | CD1: 07-Jul | CE1: 08-Jul | CF1: 09-Jul | CG1: 10-Jul | CH1: 11-Jul | CI1: 12-Jul | CJ1: 13-Jul | CK1: 14-Jul | CL1: 15-Jul | CM1: 16-Jul | CN1: 17-Jul | CO1: 18-Jul | CP1: 19-Jul | CQ1: 20-Jul | CR1: 21-Jul | CS1: 22-Jul | CT1: 23-Jul | CU1: 24-Jul | CV1: 25-Jul | CW1: 26-Jul | CX1: 27-Jul | CY1: 28-Jul | CZ1: 29-Jul | DA1: 30-Jul | DB1: 31-Jul | DC1: 01-Aug | DD1: 02-Aug | DE1: 03-Aug | DF1: 04-Aug | DG1: 05-Aug | DH1: 06-Aug | DI1: 07-Aug | DJ1: 08-Aug | DK1: 09-Aug | DL1: 10-Aug | DM1: 11-Aug | DN1: 12-Aug | DO1: 13-Aug | DP1: 14-Aug | DQ1: 15-Aug | DR1: 16-Aug | DS1: 17-Aug | DT1: 18-Aug | DU1: 19-Aug | DV1: 20-Aug | DW1: 21-Aug | DX1: 22-Aug | DY1: 23-Aug | DZ1: 24-Aug | EA1: 25-Aug | EB1: 26-Aug | EC1: 27-Aug | ED1: 28-Aug | EE1: 29-Aug | EF1: 30-Aug | EG1: 31-Aug | EH1: 01-Sep | EI1: 02-Sep | EJ1: 03-Sep | EK1: 04-Sep | EL1: 05-Sep | EM1: 06-Sep | EN1: 07-Sep | EO1: 08-Sep | EP1: 09-Sep | EQ1: 10-Sep | ER1: 11-Sep | ES1: 12-Sep | ET1: 13-Sep | EU1: 14-Sep | EV1: 15-Sep | EW1: 16-Sep | EX1: 17-Sep | EY1: 18-Sep | EZ1: 19-Sep | FA1: 20-Sep | FB1: 21-Sep | FC1: 22-Sep | FD1: 23-Sep | FE1: 24-Sep | FF1: 25-Sep | FG1: 26-Sep | FH1: 27-Sep | FI1: 28-Sep | FJ1: 29-Sep | FK1: 30-Sep | FL1: 01-Oct | FM1: 02-Oct | FN1: 03-Oct | FO1: 04-Oct | FP1: 05-Oct | FQ1: 06-Oct | FR1: 07-Oct | FS1: 08-Oct | FT1: 09-Oct | FU1: 10-Oct | FV1: 11-Oct | FW1: 12-Oct | FX1: 13-Oct | FY1: 14-Oct | FZ1: 15-Oct | GA1: 16-Oct | GB1: 17-Oct | GC1: 18-Oct | GD1: 19-Oct | GE1: 20-Oct | GF1: 21-Oct | GG1: 22-Oct | GH1: 23-Oct | GI1: 24-Oct | GJ1: 25-Oct | GK1: 26-Oct | GL1: 27-Oct | GM1: 28-Oct | GN1: 29-Oct | GO1: 30-Oct | GP1: 31-Oct | GQ1: 01-Nov | GR1: 02-Nov | GS1: 03-Nov | GT1: 04-Nov | GU1: 05-Nov | GV1: 06-Nov | GW1: 07-Nov | GX1: 08-Nov | GY1: 09-Nov | GZ1: 10-Nov | HA1: 11-Nov | HB1: 12-Nov | HC1: 13-Nov | HD1: 14-Nov | HE1: 15-Nov | HF1: 16-Nov | HG1: 17-Nov | HH1: 18-Nov | HI1: 19-Nov | HJ1: 20-Nov | HK1: 21-Nov | HL1: 22-Nov | HM1: 23-Nov | HN1: 24-Nov | HO1: 25-Nov | HP1: 26-Nov | HQ1: 27-Nov | HR1: 28-Nov | HS1: 29-Nov | HT1: 30-Nov | HU1: 01-Dec | HV1: 02-Dec | HW1: 03-Dec | HX1: 04-Dec | HY1: 05-Dec | HZ1: 06-Dec | IA1: 07-Dec | IB1: 08-Dec | IC1: 09-Dec | ID1: 10-Dec | IE1: 11-Dec | IF1: 12-Dec | IG1: 13-Dec | IH1: 14-Dec | II1: 15-Dec | IJ1: 16-Dec | IK1: 17-Dec | IL1: 18-Dec | IM1: 19-Dec | IN1: 20-Dec | IO1: 21-Dec | IP1: 22-Dec | IQ1: 23-Dec | IR1: 24-Dec | IS1: 25-Dec | IT1: 26-Dec | IU1: 27-Dec | IV1: 28-Dec | IW1: 29-Dec | IX1: 30-Dec | IY1: 31-Dec
A2: IOB-505 | E2: IOB WARMING UNIT | F2: IOB | G2: USED / DAMAGED | H2: WU202006025EN (machine only) | I2: OFFICE - PULL OUT/REPLACED - BMC | K2: =L2-M2 -> 1 | L2: 1 | M2: =SUM(O2:IY2) -> 0 | N2: =K2 -> 1
A3: IOB-505 | E3: IOB WARMING UNIT | F3: IOB | G3: USED / DAMAGED | H3: WU202001050EN (machine only) | I3: OFFICE - PULL OUT/REPLACED - AL ZAHRA | K3: =L3-M3 -> 1 | L3: 1 | M3: =SUM(O3:IY3) -> 0 | N3: =K3 -> 1
A4: IOB-505 | E4: IOB WARMING UNIT | F4: IOB | G4: USED / DAMAGED | H4: WU202001052EN (machine only) | I4: LDN/MDE-DXB-2026/4001D MEDEOR DUBAI 02-02-2026 | K4: =L4-M4 -> 0 | L4: 0 | M4: =SUM(O4:IY4) -> 0 | N4: =K4 -> 0
A5: IOB-505 | E5: IOB WARMING UNIT | F5: IOB | G5: USED / DAMAGED | H5: WU202006003EN (machine only) | I5: DN/BUR-MC-AD-2026/4003D/Return BMC 09-01-2026 | K5: =L5-M5 -> 0 | L5: 0 | M5: =SUM(O5:IY5) -> 0 | N5: =K5 -> 0
A6: IOB-505 | E6: IOB WARMING UNIT | F6: IOB | G6: USED / DAMAGED | H6: WU202208139EN (machine only) | I6: DN/BUR-MC-AD-2026/4003D/Return BMC 09-01-2026 | K6: =L6-M6 -> 0 | L6: 0 | M6: =SUM(O6:IY6) -> 0 | N6: =K6 -> 0
A7: IOB-505 | E7: IOB WARMING UNIT | F7: IOB | G7: USED / DAMAGED | H7: WU202001068EN (full set - no rolling stand) | I7: LDN-TLSH-2026-4002D - TRUE LIFE SPECIALTY HOSPITAL AA- 18-03-2026 - 1 PC | K7: =L7-M7 -> 0 | L7: 0 | M7: =SUM(O7:IY7) -> 0 | N7: =K7 -> 0
A8: IOB-505 | E8: IOB WARMING UNIT | F8: IOB | G8: USED / DAMAGED | H8: WU202006032EN (machine only) | I8: DN/MDE-DXB-2026-4001D/RETURN - MEDEOR DUBAI - 02-02-2026 | K8: =L8-M8 -> 0 | L8: 0 | M8: =SUM(O8:IY8) -> 0 | N8: =K8 -> 0
A9: IOB-505 | E9: IOB WARMING UNIT | F9: IOB | G9: USED / DAMAGED | H9: WU202202037EN (machine only) | I9: DN/SCRH-2026/4001D/Return SALMA SKMC 09-01-2026 | K9: =L9-M9 -> 0 | L9: 0 | M9: =SUM(O9:IY9) -> 0 | N9: =K9 -> 0
A10: IOB-505 | E10: IOB WARMING UNIT | F10: IOB | G10: USED / DAMAGED | H10: WU202006049EN (full set) | I10: DN/BUR-MC-AD-2026/4001D/Return - BMC - 05-01-2026 | K10: =L10-M10 -> 0 | L10: 0 | M10: =SUM(O10:IY10) -> 0 | N10: =K10 -> 0
A11: IOB-505 | B11: IOB WARMING UNIT | E11: IOB WARMING UNIT | F11: IOB | G11: USED / DAMAGED | H11: WU201907097EN | I11: OFFICE - PULL OUT: SEHA EMIRATES AD 11-09-2025 | K11: =L11-M11 -> 1 | L11: 1 | M11: =SUM(O11:IY11) -> 0 | N11: =K11 -> 1
A12: IOB-505 | B12: IOB WARMING UNIT | E12: IOB WARMING UNIT | F12: IOB | G12: USED / DAMAGED | H12: WU202006041EN (with airhose and power cord) | I12: DN-BUR-SHJ-2026-4001D-RETURN - BURJEEL SPECIALTY HOSP - SHARJAH - 04-05-2026 | K12: =L12-M12 -> 0 | L12: 1 | M12: =SUM(O12:IY12) -> 1 | N12: =K12 -> 0 | R12: =1 -> 1
A13: IOB-505 | B13: IOB WARMING UNIT | E13: IOB WARMING UNIT | F13: IOB | G13: USED / DAMAGED | H13: WU202006020EN (machine with airhose) | I13: DN-BUR-MC-AD-2026-4007D-RETURN - BMC - 18-05-2026 | K13: =L13-M13 -> 0 | L13: 1 | M13: =SUM(O13:IY13) -> 1 | N13: =K13 -> 0 | AF13: =1 -> 1
A14: IOB-505 | E14: IOB WARMING UNIT | F14: IOB | G14: FOR INSPECTION / DAMAGED | H14: WU202001063EN (with power cord) | I14: LDN/MDE-DXB-2026/4001D MEDEOR DUBAI 02-02-2026 | K14: =L14-M14 -> 0 | L14: 0 | M14: =SUM(O14:IY14) -> 0 | N14: =K14 -> 0
A15: IOB-505 | E15: IOB WARMING UNIT | F15: IOB | G15: FOR INSPECTION / DAMAGED | H15: WU202006015EN (with power cord) | I15: LDN/MDE-DXB-2026/4001D MEDEOR DUBAI 02-02-2026 | K15: =L15-M15 -> 0 | L15: 0 | M15: =SUM(O15:IY15) -> 0 | N15: =K15 -> 0
A16: WU-007 | E16: IOB AIR HOSE WITH SENSOR ONE CORD | F16: IOB | G16: FOR INSPECTION: USED / DAMAGED | H16: pull out with machine WU202001063EN & WU202001063EN | I16: DN/MDE-DXB-2026-4001D/RETURN - MEDEOR DUBAI - 02-02-2026 | K16: =L16-M16 -> 0 | L16: 0 | M16: =SUM(O16:IY16) -> 0 | N16: =K16 -> 0
A17: WU-026 | E17: IOB METAL HOSE CLAMP | F17: IOB | G17: FOR INSPECTION: USED / DAMAGED | H17: pull out with machine WU202001063EN & WU202001063EN | I17: LDN/MDE-DXB-2026/4001D MEDEOR DUBAI 02-02-2026 | K17: =L17-M17 -> 0 | L17: 0 | M17: =SUM(O17:IY17) -> 0 | N17: =K17 -> 0
A18: IOB-507 | E18: IOB WARMING UNIT | F18: IOB | G18: USED / DAMAGED | H18: WU250500140 (with airhose, powercord, rolling stand) | I18: LDN-BUR-MC-AD-2026-4001D - BMC - 17-04-2026 | K18: =L18-M18 -> 0 | L18: 0 | M18: =SUM(O18:IY18) -> 0 | N18: =K18 -> 0
A19: IOB-507 | E19: IOB WARMING UNIT | F19: IOB | G19: NEW (26-01-2026) | H19: WU251100221 | 14/11/2025 | I19: LDN/MDE-AD-2026/4001D MEDEOR-AD 27-01-2026 | K19: =L19-M19 -> 0 | L19: 0 | M19: =SUM(O19:IY19) -> 0 | N19: =K19 -> 0
A20: IOB-507 | E20: IOB WARMING UNIT | F20: IOB | G20: NEW (26-01-2026) | H20: WU251100222 | 14/11/2025 | I20: LDN/MDE-AD-2026/4001D MEDEOR-AD 27-01-2026 | K20: =L20-M20 -> 0 | L20: 0 | M20: =SUM(O20:IY20) -> 0 | N20: =K20 -> 0
A21: IOB-507 | E21: IOB WARMING UNIT | F21: IOB | G21: NEW (26-01-2026) | H21: WU251100223 | 14/11/2025 | I21: LDN-BUR-SHJ-2026-4001D BUR SPECIALTY SHJ 28-01-2026 | K21: =L21-M21 -> 0 | L21: 0 | M21: =SUM(O21:IY21) -> 0 | N21: =K21 -> 0
A22: IOB-507 | E22: IOB WARMING UNIT | F22: IOB | G22: NEW (26-01-2026) | H22: WU251100224 | 14/11/2025 | I22: LDN-BUR-SHJ-2026-4001D BUR SPECIALTY SHJ 28-01-2026 | K22: =L22-M22 -> 0 | L22: 0 | M22: =SUM(O22:IY22) -> 0 | N22: =K22 -> 0
A23: IOB-507 | E23: IOB WARMING UNIT | F23: IOB | G23: NEW (26-01-2026) | H23: WU251100225 | 14/11/2025 | I23: LDN-BUR-SHJ-2026-4001D BUR SPECIALTY SHJ 28-01-2026 | K23: =L23-M23 -> 0 | L23: 0 | M23: =SUM(O23:IY23) -> 0 | N23: =K23 -> 0
A24: IOB-507 | E24: IOB WARMING UNIT | F24: IOB | G24: NEW (26-01-2026) | H24: WU251200321 | 06/12/2025 | I24: LDN/BRHA-2026/4001D - BURJEEL ROYAL ASHAREJ AL AIN - 29-01-2026 | K24: =L24-M24 -> 0 | L24: 0 | M24: =SUM(O24:IY24) -> 0 | N24: =K24 -> 0
A25: IOB-507 | E25: IOB WARMING UNIT | F25: IOB | G25: NEW (26-01-2026) | H25: WU251200322 | 06/12/2025 | I25: LDN/BRHA-2026/4001D - BURJEEL ROYAL ASHAREJ AL AIN - 29-01-2026 | K25: =L25-M25 -> 0 | L25: 0 | M25: =SUM(O25:IY25) -> 0 | N25: =K25 -> 0
... A33: IOB-507 | E33: IOB WARMING UNIT | F33: IOB | G33: NEW (26-01-2026) | H33: WU251200330 | 06/12/2025 | I33: OFFICE | K33: =L33-M33 -> 1 | L33: 1 | M33: =SUM(O33:IY33) -> 0 | N33: =K33 -> 1
A34: WU-5-006 | E34: IOB BASEBOARD | F34: IOB | G34: NEW | I34: OFFICE | K34: =L34-M34 -> 8 | L34: =5+4 -> 9 | M34: =SUM(O34:IY34) -> 1 | N34: =K34 -> 8 | R34: =1 -> 1
A35: WU-007 | E35: IOB AIR HOSE WITH SENSOR ONE CORD | F35: IOB | G35: NEW | I35: OFFICE | K35: =L35-M35 -> 5 | L35: 6 | M35: =SUM(O35:IY35) -> 1 | N35: =K35 -> 5 | AF35: =1 -> 1
A36: WU-007 | E36: IOB AIR HOSE WITH SENSOR ONE CORD | F36: IOB | G36: USED / DAMAGED | I36: DN/BUR-MCAD-2026/4002D/FOC BMC 26-01-2026 | K36: =L36-M36 -> 0 | L36: 0 | M36: =SUM(O36:IY36) -> 0 | N36: =K36 -> 0
A37: WU-007 | E37: IOB AIR HOSE WITH SENSOR ONE CORD | F37: IOB | G37: USED / DAMAGED | I37: DN/AACS-2026/4002D/RETURN AMERICAN ACADEMY 19-01-2026 (1 PC) | K37: =L37-M37 -> 0 | L37: 0 | M37: =SUM(O37:IY37) -> 0 | N37: =K37 -> 0
A38: WU-007 | E38: IOB AIR HOSE WITH SENSOR ONE CORD | F38: IOB | G38: USED / DAMAGED | I38: OFFICE - Pull Out-BUR-MCAD-2026-4009D - BMC - 21-01-2026 | K38: =L38-M38 -> 2 | L38: 2 | M38: =SUM(O38:IY38) -> 0 | N38: =K38 -> 2
A39: WU-007 | E39: IOB AIR HOSE WITH SENSOR ONE CORD | F39: IOB | G39: USED / DAMAGED | I39: DN/BUR-MC-AD-2026/4005D/Return - BMC - 16-02-2026 | K39: =L39-M39 -> 0 | L39: 0 | M39: =SUM(O39:IY39) -> 0 | N39: =K39 -> 0
A40: WU-007 | E40: IOB AIR HOSE WITH SENSOR ONE CORD | F40: IOB | G40: USED / DAMAGED | I40: OFFICE - Pull Out-BUR-MCAD-2026-4012D - BMC - 05-02-2026 | K40: =L40-M40 -> 0 | L40: 0 | M40: =SUM(O40:IY40) -> 0 | N40: =K40 -> 0
A41: WU-007 | E41: IOB AIR HOSE WITH SENSOR ONE CORD | F41: IOB | G41: USED / DAMAGED | I41: DN-AST-M-2026-4001D-RETURN - ASTER MANKHOOL - 12-05-2026 | K41: =L41-M41 -> 0 | L41: 1 | M41: =SUM(O41:IY41) -> 1 | N41: =K41 -> 0 | Z41: =1 -> 1
A42: WU-007 | E42: IOB AIR HOSE WITH SENSOR ONE CORD | F42: IOB | G42: USED / DAMAGED | I42: OFFICE - Pull Out-MGH-HCC-2026-4023D - MEDICLINIC CITY - 12-05-2026 | K42: =L42-M42 -> 1 | L42: 1 | M42: =SUM(O42:IY42) -> 0 | N42: =K42 -> 1
A43: WU-008 | E43: IOB ELBOW WITH SENSOR TWO CORD | F43: IOB | G43: NEW | I43: OFFICE | K43: =L43-M43 -> 3 | L43: 3 | M43: =SUM(O43:IY43) -> 0 | N43: =K43 -> 3
A44: IOB ROLLING STAND WHEELS | E44: IOB ROLLING STAND WHEELS | F44: IOB | G44: NEW | I44: OFFICE | K44: =L44-M44 -> 4 | L44: 4 | M44: =SUM(O44:IY44) -> 0 | N44: =K44 -> 4
A45: WU-010 | E45: INITIAL FILTER | F45: IOB | G45: NEW | I45: OFFICE | K45: =L45-M45 -> 77 | L45: =2+75 -> 77 | M45: =SUM(O45:IY45) -> 0 | N45: =K45 -> 77
A46: WU-011 | E46: NOISE BOARD ASSY | F46: IOB | G46: NEW (09-05-2026) | I46: OFFICE | K46: =L46-M46 -> 1 | L46: 1 | M46: =SUM(O46:IY46) -> 0 | N46: =K46 -> 1
A47: WU-026 | E47: IOB METAL HOSE CLAMP | F47: IOB | G47: NEW | I47: LDN/MDE-DXB-2026/4001D MEDEOR DUBAI 02-02-2026 | K47: =L47-M47 -> 0 | L47: 0 | M47: =SUM(O47:IY47) -> 0 | N47: =K47 -> 0
...

Sheet STOCK WARNING
A1: ITEM | B1: WARNING QTY | C1: REMAINING STOCK AS OF 26-02-2026 (MANUAL) | D1: REMAINING STOCK (FORMULA) | E1: EQUAL? | F1: WARNING NOTIFICATION | G1: DIFFERENCE
A2: IOB-004 | B2: 7000 | C2: 6183 | D2: ='DISPOSABLE ITEMS'!M20 -> 6733 | E2: =IF(C2=D2,"OK","XX") -> XX | F2: =IF(D2<B2,"BELOW REORDER QTY","QUANTITY ABOVE WARNING") -> BELOW REORDER QTY | G2: =B2-D2 -> 267
A3: IOB-003 | B3: 800 | C3: 727 | D3: ='DISPOSABLE ITEMS'!M13 -> 767 | E3: =IF(C3=D3,"OK","XX") -> XX | F3: =IF(D3<B3,"BELOW REORDER QTY","QUANTITY ABOVE WARNING") -> BELOW REORDER QTY | G3: =B3-D3 -> 33
A4: IOB-002 | B4: 280 | C4: 564 | D4: ='DISPOSABLE ITEMS'!M6 -> 24 | E4: =IF(C4=D4,"OK","XX") -> XX | F4: =IF(D4<B4,"BELOW REORDER QTY","QUANTITY ABOVE WARNING") -> BELOW REORDER QTY | G4: =B4-D4 -> 256
A5: IOB-007 | B5: 400 | C5: 865 | D5: ='DISPOSABLE ITEMS'!M27 -> 224 | E5: =IF(C5=D5,"OK","XX") -> XX | F5: =IF(D5<B5,"BELOW REORDER QTY","QUANTITY ABOVE WARNING") -> BELOW REORDER QTY | G5: =B5-D5 -> 176
A6: IOB-012 | B6: 100 | C6: 332 | D6: ='DISPOSABLE ITEMS'!M33 -> 322 | E6: =IF(C6=D6,"OK","XX") -> XX | F6: =IF(D6<B6,"BELOW REORDER QTY","QUANTITY ABOVE WARNING") -> QUANTITY ABOVE WARNING | G6: =B6-D6 -> -222
A7: IOB-006 | B7: 100 | C7: 490 | D7: ='DISPOSABLE ITEMS'!M21 -> 370 | E7: =IF(C7=D7,"OK","XX") -> XX | F7: =IF(D7<B7,"BELOW REORDER QTY","QUANTITY ABOVE WARNING") -> QUANTITY ABOVE WARNING | G7: =B7-D7 -> -270
A8: IOB-008 | B8: 200 | C8: 640 | D8: ='DISPOSABLE ITEMS'!M30 -> 420 | E8: =IF(C8=D8,"OK","XX") -> XX | F8: =IF(D8<B8,"BELOW REORDER QTY","QUANTITY ABOVE WARNING") -> QUANTITY ABOVE WARNING | G8: =B8-D8 -> -220
A9: IOB-028 | B9: 400 | C9: 514 | D9: ='DISPOSABLE ITEMS'!M48 -> 499 | E9: =IF(C9=D9,"OK","XX") -> XX | F9: =IF(D9<B9,"BELOW REORDER QTY","QUANTITY ABOVE WARNING") -> QUANTITY ABOVE WARNING | G9: =B9-D9 -> -99
A10: IOB-009 | B10: 120 | C10: 390 | D10: ='DISPOSABLE ITEMS'!M32 -> 390 | E10: =IF(C10=D10,"OK","XX") -> OK | F10: =IF(D10<B10,"BELOW REORDER QTY","QUANTITY ABOVE WARNING") -> QUANTITY ABOVE WARNING | G10: =B10-D10 -> -270
A11: IOB-025 | B11: 100 | C11: 465 | D11: ='DISPOSABLE ITEMS'!M40 -> 465 | E11: =IF(C11=D11,"OK","XX") -> OK | F11: =IF(D11<B11,"BELOW REORDER QTY","QUANTITY ABOVE WARNING") -> QUANTITY ABOVE WARNING | G11: =B11-D11 -> -365
A12: IOB-016 | B12: 240 | C12: 409 | D12: ='DISPOSABLE ITEMS'!M38 -> 79 | E12: =IF(C12=D12,"OK","XX") -> XX | F12: =IF(D12<B12,"BELOW REORDER QTY","QUANTITY ABOVE WARNING") -> BELOW REORDER QTY | G12: =B12-D12 -> 161
A13: BOV-300-S / LBTK500-S | B13: 450 | C13: =123+750 -> 873 | D13: ='DISPOSABLE ITEMS'!M52+'DISPOSABLE ITEMS'!M75 -> 113 | E13: =IF(C13=D13,"OK","XX") -> XX | F13: =IF(D13<B13,"BELOW REORDER QTY","QUANTITY ABOVE WARNING") -> BELOW REORDER QTY | G13: =B13-D13 -> 337
A14: BOV-300-M / LBTK500-M | B14: 1000 | C14: =83+1450 -> 1533 | D14: ='DISPOSABLE ITEMS'!M57+'DISPOSABLE ITEMS'!M77 -> 42 | E14: =IF(C14=D14,"OK","XX") -> XX | F14: =IF(D14<B14,"BELOW REORDER QTY","QUANTITY ABOVE WARNING") -> BELOW REORDER QTY | G14: =B14-D14 -> 958
A15: BOV-300-L / LBTK500-L | B15: 500 | C15: =56+730 -> 786 | D15: ='DISPOSABLE ITEMS'!M60+'DISPOSABLE ITEMS'!M79 -> 103 | E15: =IF(C15=D15,"OK","XX") -> XX | F15: =IF(D15<B15,"BELOW REORDER QTY","QUANTITY ABOVE WARNING") -> BELOW REORDER QTY | G15: =B15-D15 -> 397
A16: BOV-301-S / LBTK502-S | B16: 100 | C16: =258+100 -> 358 | D16: ='DISPOSABLE ITEMS'!M63+'DISPOSABLE ITEMS'!M80 -> 352 | E16: =IF(C16=D16,"OK","XX") -> XX | F16: =IF(D16<B16,"BELOW REORDER QTY","QUANTITY ABOVE WARNING") -> QUANTITY ABOVE WARNING | G16: =B16-D16 -> -252
A17: BOV-301-M / LBTK502-M | B17: 350 | C17: =186+460 -> 646 | D17: ='DISPOSABLE ITEMS'!M66+'DISPOSABLE ITEMS'!M82 -> 395 | E17: =IF(C17=D17,"OK","XX") -> XX | F17: =IF(D17<B17,"BELOW REORDER QTY","QUANTITY ABOVE WARNING") -> QUANTITY ABOVE WARNING | G17: =B17-D17 -> -45
A18: BOV-301-L / LBTK502-L | B18: 350 | C18: =0+108 -> 108 | D18: ='DISPOSABLE ITEMS'!M70+'DISPOSABLE ITEMS'!M84 -> 30 | E18: =IF(C18=D18,"OK","XX") -> XX | F18: =IF(D18<B18,"BELOW REORDER QTY","QUANTITY ABOVE WARNING") -> BELOW REORDER QTY | G18: =B18-D18 -> 320
A19: BOV-301-XL | B19: 100 | C19: =501 -> 501 | D19: ='DISPOSABLE ITEMS'!M72 -> 83 | E19: =IF(C19=D19,"OK","XX") -> XX | F19: =IF(D19<B19,"BELOW REORDER QTY","QUANTITY ABOVE WARNING") -> BELOW REORDER QTY | G19: =B19-D19 -> 17
A20: 6111S | B20: 50 | C20: 134 | D20: ='DISPOSABLE ITEMS'!M106 -> 134 | E20: =IF(C20=D20,"OK","XX") -> OK | F20: =IF(D20<B20,"BELOW REORDER QTY","QUANTITY ABOVE WARNING") -> QUANTITY ABOVE WARNING | G20: =B20-D20 -> -84
A21: 6111M | B21: 50 | C21: 164 | D21: ='DISPOSABLE ITEMS'!M108 -> 158 | E21: =IF(C21=D21,"OK","XX") -> XX | F21: =IF(D21<B21,"BELOW REORDER QTY","QUANTITY ABOVE WARNING") -> QUANTITY ABOVE WARNING | G21: =B21-D21 -> -108
A22: 6111L | B22: 50 | C22: 8 | D22: ='DISPOSABLE ITEMS'!M109 -> 2 | E22: =IF(C22=D22,"OK","XX") -> XX | F22: =IF(D22<B22,"BELOW REORDER QTY","QUANTITY ABOVE WARNING") -> BELOW REORDER QTY | G22: =B22-D22 -> 48
A23: 6111XL | B23: 70 | C23: 3 | D23: ='DISPOSABLE ITEMS'!M110 -> 0 | E23: =IF(C23=D23,"OK","XX") -> XX | F23: =IF(D23<B23,"BELOW REORDER QTY","QUANTITY ABOVE WARNING") -> BELOW REORDER QTY | G23: =B23-D23 -> 70
A24: 6111XXL | B24: 70 | C24: 0 | D24: ='DISPOSABLE ITEMS'!M112 -> 0 | E24: =IF(C24=D24,"OK","XX") -> OK | F24: =IF(D24<B24,"BELOW REORDER QTY","QUANTITY ABOVE WARNING") -> BELOW REORDER QTY | G24: =B24-D24 -> 70
A25: 6121S | B25: 150 | C25: 237 | D25: ='DISPOSABLE ITEMS'!M89 -> 327 | E25: =IF(C25=D25,"OK","XX") -> XX | F25: =IF(D25<B25,"BELOW REORDER QTY","QUANTITY ABOVE WARNING") -> QUANTITY ABOVE WARNING | G25: =B25-D25 -> -177
A26: 6121M | B26: 250 | C26: 80 | D26: ='DISPOSABLE ITEMS'!M94 -> 294 | E26: =IF(C26=D26,"OK","XX") -> XX | F26: =IF(D26<B26,"BELOW REORDER QTY","QUANTITY ABOVE WARNING") -> QUANTITY ABOVE WARNING | G26: =B26-D26 -> -44
A27: 6121L | B27: 450 | C27: 793 | D27: ='DISPOSABLE ITEMS'!M98 -> 482 | E27: =IF(C27=D27,"OK","XX") -> XX | F27: =IF(D27<B27,"BELOW REORDER QTY","QUANTITY ABOVE WARNING") -> QUANTITY ABOVE WARNING | G27: =B27-D27 -> -32
A28: 6121XL | B28: 750 | C28: 403 | D28: ='DISPOSABLE ITEMS'!M101 -> 871 | E28: =IF(C28=D28,"OK","XX") -> XX | F28: =IF(D28<B28,"BELOW REORDER QTY","QUANTITY ABOVE WARNING") -> QUANTITY ABOVE WARNING | G28: =B28-D28 -> -121
A29: 6121XXL | B29: 700 | C29: 33 | D29: ='DISPOSABLE ITEMS'!M104 -> 901 | E29: =IF(C29=D29,"OK","XX") -> XX | F29: =IF(D29<B29,"BELOW REORDER QTY","QUANTITY ABOVE WARNING") -> QUANTITY ABOVE WARNING | G29: =B29-D29 -> -201
A30: TD01 | B30: 17000 | C30: 45325 | D30: ='DISPOSABLE ITEMS'!M120 -> 50075 | E30: =IF(C30=D30,"OK","XX") -> XX | F30: =IF(D30<B30,"BELOW REORDER QTY","QUANTITY ABOVE WARNING") -> QUANTITY ABOVE WARNING | G30: =B30-D30 -> -33075
A31: TR03 | B31: 2500 | C31: 650 | D31: ='DISPOSABLE ITEMS'!M116 -> 9997 | E31: =IF(C31=D31,"OK","XX") -> XX | F31: =IF(D31<B31,"BELOW REORDER QTY","QUANTITY ABOVE WARNING") -> QUANTITY ABOVE WARNING | G31: =B31-D31 -> -7497
A32: YC.001 | B32: 1200 | C32: 1340 | D32: ='DISPOSABLE ITEMS'!M126 -> 232 | E32: =IF(C32=D32,"OK","XX") -> XX | F32: =IF(D32<B32,"BELOW REORDER QTY","QUANTITY ABOVE WARNING") -> BELOW REORDER QTY | G32: =B32-D32 -> 968
A33: YC.002 | B33: 3000 | C33: 1970 | D33: ='DISPOSABLE ITEMS'!M130 -> 34 | E33: =IF(C33=D33,"OK","XX") -> XX | F33: =IF(D33<B33,"BELOW REORDER QTY","QUANTITY ABOVE WARNING") -> BELOW REORDER QTY | G33: =B33-D33 -> 2966
A34: CM631 | B34: 700 | C34: 248 | D34: ='DISPOSABLE ITEMS'!J146 -> 0 | E34: =IF(C34=D34,"OK","XX") -> XX | F34: =IF(D34<B34,"BELOW REORDER QTY","QUANTITY ABOVE WARNING") -> BELOW REORDER QTY | G34: =B34-D34 -> 700
A35: OBS-MW | B35: 100 | C35: 599 | D35: ='DISPOSABLE ITEMS'!M144 -> 479 | E35: =IF(C35=D35,"OK","XX") -> XX | F35: =IF(D35<B35,"BELOW REORDER QTY","QUANTITY ABOVE WARNING") -> QUANTITY ABOVE WARNING | G35: =B35-D35 -> -379
A36: GS2212 | B36: 0 | C36: 3584 | D36: ='DISPOSABLE ITEMS'!M134 -> 2682 | E36: =IF(C36=D36,"OK","XX") -> XX | F36: =IF(D36<B36,"BELOW REORDER QTY","QUANTITY ABOVE WARNING") -> QUANTITY ABOVE WARNING | G36: =B36-D36 -> -2682
A37: GS4412 | B37: 500 | C37: 8300 | D37: ='DISPOSABLE ITEMS'!M136 -> 7198 | E37: =IF(C37=D37,"OK","XX") -> XX | F37: =IF(D37<B37,"BELOW REORDER QTY","QUANTITY ABOVE WARNING") -> QUANTITY ABOVE WARNING | G37: =B37-D37 -> -6698
A38: GSS2212 | B38: 300 | C38: 1524 | D38: ='DISPOSABLE ITEMS'!M137 -> -1 | E38: =IF(C38=D38,"OK","XX") -> XX | F38: =IF(D38<B38,"BELOW REORDER QTY","QUANTITY ABOVE WARNING") -> BELOW REORDER QTY | G38: =B38-D38 -> 301
A39: GSS4412 | B39: 1500 | C39: 3233 | D39: ='DISPOSABLE ITEMS'!M140 -> 0 | E39: =IF(C39=D39,"OK","XX") -> XX | F39: =IF(D39<B39,"BELOW REORDER QTY","QUANTITY ABOVE WARNING") -> BELOW REORDER QTY | G39: =B39-D39 -> 1500
A40: GSS4412X | B40: 2000 | C40: 6817 | D40: ='DISPOSABLE ITEMS'!M142 -> 1852 | E40: =IF(C40=D40,"OK","XX") -> XX | F40: =IF(D40<B40,"BELOW REORDER QTY","QUANTITY ABOVE WARNING") -> BELOW REORDER QTY | G40: =B40-D40 -> 148

Sheet DDL
A1: STATUS
A2: EXPIRED
A3: FAR EXP
A4: MIDDLE EXP
A5: NEAR EXP
A6: NEW DELIVERY
A7: OUT OF STOCK
A8: REPLACEMENT
A9: OLD SHIPMENT
A10: PULL OUT
A11: DAMAGED
A12: REPAIRED
A13: SOLD
