Workbook

Sheet Contacts List
A1: ITEM | B1: COMPANY | C1: EMAIL | D1: PHONE | E1: NAME | F1: ROLE
A2: ULTRASOUND GEL | B2: Tianjin Grand Paper Industry Co., Ltd | C2: saleszhao@163.com | D2: 86-13116005267 | E2: Ms. Melissa | F2: Sales
A3: IOB | B3: Jiangmen Dacheng Medical Equipment Co., Ltd | C3: jessie.ho@IOBmedical.com | D3: +8613426759970 | E3: Ms. Jessie
A4: IOB | B4: Jiangmen Dacheng Medical Equipment Co., Ltd | C4: Rachel.DiMauro@gentherm.com | D4: +44 (0)7721 584802 | E4: Ms. Rachel
A5: SLEEVES | B5: Suzhou Minha Medical Equipment Co., LTD | C5: katya_kajiya@163.com | E5: Ms. Katya
A6: SLEEVES | B6: Dalian Labtek Science & Development Co., LTD | C6: simon@labtek-med.com
A7: GAUZE | B7: JIUJANG HUADA MEDICAL DRESSING CO., LTD | C7: kaci@huadamedical.com | E7: Kaci
A8: SKIN MARKER | B8: Dongguan Tondaus Meditech Co., LTD | C8: s1@tondaus.com | D8: +8618819703898 | E8: Elaine
A9: SWAB APPLICATOR | B9: CareNow Medical Pvt Ltd. | C9: abhishek.m@healthiummedtech.com | D9: (+91) 9644692535 | E9: Abhishek Mishra
A10: SWAB APPLICATOR | B10: CareNow Medical Pvt Ltd. | C10: nishant.g@healthiummedtech.com | F10: CC
A11: SWAB APPLICATOR | B11: CareNow Medical Pvt Ltd. | C11: kedar.d@healthiummedtech.com | F11: CC
A12: SWAB APPLICATOR | B12: CareNow Medical Pvt Ltd. | C12: aravind.a@healthiummedtech.com
A13: PROJECTION VEIN FINDER | B13: Shenzhen Vivolight Medical Device & Technology Co., Ltd | C13: LizChen@vivo-light.com | D13: +86 15220244172 | E13: Liz Chen | F13: Overseas Sales Manager
A14: STOCKINGS | B14: Varimed Medikal San. Ve. Tic. Ltd. | C14: exim1@varimed.com.tr | F14: MAIN
A15: STOCKINGS | B15: Varimed Medikal San. Ve. Tic. Ltd. | C15: volkan@varimed.com.tr | F15: CC
A16: STOCKINGS | B16: Varimed Medikal San. Ve. Tic. Ltd. | C16: export-import@varimed.com.tr | F16: CC
A17: STOCKINGS | B17: Varimed Medikal San. Ve. Tic. Ltd. | C17: gonca@varimed.com.tr | F17: CC
A18: FORWARDER (UAE) | B18: AFC | C18: falah@afcsworld.com | D18: +971522563355 | E18: Falah
A19: FORWARDER (UAE) | B19: AFC | C19: amjad@afcsworld.com | E19: Amjad
A20: FORWARDER (UAE) | B20: FASTCONNECT | C20: admin@fastconnect-fze.com | D20: +97145148698 | E20: Sameer
A21: FORWARDER (UAE) | B21: FASTCONNECT | C21: shareef@fastconnect-fze.com | D21: +971554497992 | E21: Shareef
A22: FORWARDER (CHINA) | B22: Dalian Yuanjing International Logistics Co.,Ltd | C22: 3197475390@qq.com | E22: Xiao Ma
A23: FORWARDER (CHINA) | B23: Evergreen International Logistics Corp. (Guangzhou) | C23: victorwei@cn.evergreen-logistics.com | D23: +86 13922500537 | E23: Victor Wei
A24: FORWARDING AGENT (CHN) | B24: (AFC) PORTEVER SHIPPING (SHENZHEN) LTD. | C24: sznnmn-7@portever.com | D24: +86-755-1802228515 | E24: Vita | F24: Customer Representative
A25: FORWARDING AGENT (CHN) | B25: (AFC) FOREFRONT INTERNATIONAL NETWORK | C25: candy_shen@ff-network.com.cn | D25: (86)5923167084 | E25: Candy Shen | F25: Overseas Business Supervisor
A26: FORWARDING AGENT (CHN) | B26: (AFC) China Coast Freight Co., Ltd. Shenzhen Branch | C26: cs2.exp.szx@chinacoast.com.cn cs2.exp.szx@chinacoast.com.cn | D26: +86 755 2519 1790 | E26: Naomi Nie | F26: Customer Service Dept

Sheet SUMMARY
A1: FILE (HARD COPIES) | B1: PL |PO TO GC | C1: PO/INV NO. | D1: ITEM | E1: DELIVERY STATUS | F1: ETD | G1: APPROX RECEIVE DATE | H1: LAST UPDATE | I1: AFC INVOICE NO. | J1: REMARKS
B2: PL | PO | C2: ='SKIN MARKER - TONDAUS'!C4 -> PO-DTMCL-2026-001 | D2: ='SKIN MARKER - TONDAUS'!C5 -> SKIN MARKER | E2: ='SKIN MARKER - TONDAUS'!C28 -> IN TRANSIT | F2: ='SKIN MARKER - TONDAUS'!C25 -> 46118 | H2: ='SKIN MARKER - TONDAUS'!C31 -> # 17. Shipment arrived in Jebel Ali | Original Hard copies on hand | Paid 50% of AFC invoice
A3: SENT TO AFC | B3: PL |PO | C3: ='STOCKINGS - VARIMED'!C4 -> PO-VARIMED-2026-001 | D3: ='STOCKINGS - VARIMED'!C5 -> STOCKINGS | E3: ='STOCKINGS - VARIMED'!C32 -> RECEIVED: 21-04-2026 | F3: ='STOCKINGS - VARIMED'!C29 -> DEPARTED | H3: ='STOCKINGS - VARIMED'!C35 -> # 13. AFC INVOICE PAID 24-04-2026 | I3: SENT TO ACCT
C4: ='ELECTROSURGICAL PENCIL - ZHEJIA'!C4 -> PO-ZMTC-2026-001 | D4: ='ELECTROSURGICAL PENCIL - ZHEJIA'!C5 -> PUSH BUTTON ELECTROSURGICAL PENCIL | H4: ='ELECTROSURGICAL PENCIL - ZHEJIA'!C30 -> # 1. PO CREATED, SENT TO AMR FOR ARBAB'S APPROVAL - CANCELLED
B5: PL |PO | C5: ='LABTEK - SLEEVES-MACHINE'!C4 -> PO/DLSD-2026/001 | D5: ='LABTEK - SLEEVES-MACHINE'!C5 -> LABTEK MACHINES AND SLEEVES | E5: ='LABTEK - SLEEVES-MACHINE'!C37 -> FOR PICKUP | F5: ='LABTEK - SLEEVES-MACHINE'!C34 -> 46127 | H5: ='LABTEK - SLEEVES-MACHINE'!C40 -> # 7. MOH APPROVAL: PL WITH ALL DETAILS RECEIVED | FIRST PART PROCESSING BY NJ
B6: PL | PO | C6: ='IOB BLANKET-MACHINE'!C4 -> PO/IOB-2026/001 | D6: ='IOB BLANKET-MACHINE'!C5 -> BLANKET/MACHINE SPARE PARTS | E6: ='IOB BLANKET-MACHINE'!C37 -> IN TRANSIT | F6: ='IOB BLANKET-MACHINE'!C34 -> 46118 | H6: ='IOB BLANKET-MACHINE'!C39 -> # 8. Shipment arrived in Jebel Ali | Original Hard copies on hand | Paid 50% of AFC invoice
B7: PO | C7: ='ULTRASOUND GEL - TIANJIN'!C4 -> PO-TGP-2026-001 | D7: ='ULTRASOUND GEL - TIANJIN'!C5 -> ULTRASOUND GEL | E7: ='ULTRASOUND GEL - TIANJIN'!C28 -> IN PRODUCTION | F7: ='ULTRASOUND GEL - TIANJIN'!C25 -> NO DATE YET | H7: ='ULTRASOUND GEL - TIANJIN'!C33 -> 3. PAID 03-04-2026, FUND TRANSFER RECEIPT SENT TO TIANJIN
B8: PO | C8: ='GAUZE - JIUJIANG HUADA'!C4 -> PO/JHMD-2026/001 | D8: ='GAUZE - JIUJIANG HUADA'!C5 -> GAUZE | E8: ='GAUZE - JIUJIANG HUADA'!C33 -> IN PRODUCTION | F8: ='GAUZE - JIUJIANG HUADA'!C30 -> NO DATE YET | H8: ='GAUZE - JIUJIANG HUADA'!C35 -> # 2. PAID - WAITING FOR PACKING LIST

Sheet SKIN MARKER - TONDAUS
A1: PO DETAILS | B1: YEAR | C1: 2026
B2: PO DATE | C2: 46057
B3: VENDOR | C3: Dongguan Tondaus Meditech Co., LTD
B4: PO NO. | C4: PO-DTMCL-2026-001
B5: ITEM | C5: SKIN MARKER
C6: ITEM CODE | D6: DESCRIPTION | E6: QTY | F6: PRICE USD | G6: TOTAL USD | H6: TOTAL USD
B7: ITEM 1 | C7: TR03 | D7: Surgical Skin Marker Single Side | E7: 13000 | F7: 0.21 | G7: =(E7*F7) -> 2730 | H7: =SUM(G7:G8) -> 10430
B8: ITEM 2 | C8: TD01 | D8: Surgical Skin Marker Double Side | E8: 35000 | F8: 0.22 | G8: =(E8*F8) -> 7700
A10: FUND TRANSFER | B10: PAYMENT STATUS | C10: PAID
B11: PAYMENT DATE | C11: 46064
B12: SUBMITTED BY | C12: MUJEEB
B13: INV NO. | C13: 2026020802
A15: SHIPPER | B15: PRODUCTION STATUS
B16: SHIPPER'S REQUEST
B17: SHIPPER'S UPDATE | C17: UDPATED DELIVERY DATE: 22-03-2026
A19: FORWARDER | B19: FORWARDER
B20: FORWARDER'S REQUEST
B21: FORWARDER'S UPDATE
A23: COLLECTION / DELIVERY | B23: SHIPPER-FORWARDER STATUS | C23: CONNECTED
B24: COLLECTION DATE
B25: ETD: CHINA | C25: 46118
B26: ETA: UAE
B27: ETA: OFFICE
B28: DELIVERY STATUS | C28: IN TRANSIT
C30: *** THIS SHIPMENT HAS DUMMY INVOICE *** already noted not to send invoice to forwarders
A31: MY ACTION / UPDATES | B31: LAST UPDATE | C31: # 17. Shipment arrived in Jebel Ali | Original Hard copies on hand | Paid 50% of AFC invoice
C32: 1. SENT PO TO MANUFACTURER
C33: 2. PI RECEIVED, WILL PROCESS FUND TRANSFER
C34: 3. FUND TRANSFER DETAILS CONFIRMED BY TONDAUS, WE WILL ASK AMR WHEN TO PROCESS THE PAYMENT
C35: 4. FUND TRANSFER SIGNED, WILL GIVE TO MUJEEB TO PROCESS THE PAYMENT
C36: 5. FUND TRANSFER RECEIPT SENT, WILL WAIT FOR PACKING LIST TO SEND TO FORWARDERS
C37: 6. Invoice and Packing list received. Requesting for dummy invoice before sending it to AFC
C38: 7. PL and Dummy Invoice sent to AFC for quotation
C39: 8. AFC sent freight quotation: OCEAN FREIGHT + LOCAL CLEARANCE = AED 3030 + 873.5 + CUSTOM DUTY 1088.9 approx ( AED4992.4 /- Approx)
C40: 9. confirming freight charges with Yuanjing, and booking dates
B41: ACTION TAKEN | C41: 10. Cancelled transaction with Yuanjing, proceed option with AFC OCEAN FREIGHT + LOCAL CLEARANCE = AED 2400 + 873.5 + CUSTOM DUTY 1088.9 approx ( AED4362.4 /- Approx)
C42: 11. AFC UPDATE FREIGHT CHARGES: OCEAN FREIGHT + LOCAL CLEARANCE = AED 2670 + 873.5 + CUSTOM DUTY 1088.9 approx ( AED4632.4 /- Approx)
C43: 12. AFC UPDATE FREIGHT CHARGES: OCEAN FREIGHT + LOCAL CLEARANCE = 5,810.90 AED (IF INLAND CHARGES APPLIED: 7,343.58 AED)
C44: 13. WAITING FOR FREIGHT CHARGES FROM AFC
C45: 14. CONFIRMED FREIGHT CHARGES FROM AFC | PICK UP: 26-03-2026 | ETD: 01-04-2026
...

Sheet IOB BLANKET-MACHINE
A1: PO DETAILS | B1: YEAR | C1: 2026
B2: PO DATE | C2: 46093
B3: VENDOR | C3: Jiangmen Dacheng Medical Equipment Co., Ltd
B4: PO NO. | C4: PO/IOB-2026/001
B5: ITEM | C5: BLANKET/MACHINE SPARE PARTS
C6: ITEM CODE | D6: DESCRIPTION | E6: QTY | F6: PRICE USD | G6: TOTAL USD | H6: TOTAL USD
B7: ITEM 1 | C7: IOB-003 | D7: Intraoperative Warming Blanket Upper Body 80" x 25" (202 cm x 64 cm) | E7: 1400 | F7: 2.2 | G7: =E7*F7 -> 3080 | H7: =SUM(G7:G14) -> 29409.47
B8: ITEM 2 | C8: IOB-004 | D8: Intraoperative Warming Blanket Adult Full Body 83" x 47" (210 cm x 120 cm) | E8: 11000 | F8: 2.2 | G8: =E8*F8 -> 24200
B9: ITEM 3 | C9: IOB-028 | D9: Pediatric Warming Blanket Infant Under Body 39" x 39" (100cm X 100cm) | E9: 400 | F9: 2.2 | G9: =E9*F9 -> 880
B10: ITEM 4 | C10: WU-025 | D10: ROLLING STAND | E10: 4 | F10: 113.3 | G10: =E10*F10 -> 453.2
B11: ITEM 5 | C11: WU-5-006 | D11: BASE BOARD, IOB BLW 505 | E11: 4 | F11: 135.96 | G11: =E11*F11 -> 543.84
B12: ITEM 6 | C12: WU-010 | D12: INITIAL FILTER, IOB BLW 505/507 | E12: 75 | F12: 1.13 | G12: =E12*F12 -> 84.75
B13: ITEM 7 | C13: WU-011 | D13: NOISE BOARD ASSY, IOB BLW 505/507 | E13: 1 | F13: 31.72 | G13: =E13*F13 -> 31.72
B14: ITEM 8 | C14: WU-037 | D14: ALUM HOOK BACK ASSY, IOB 505/507 | E14: 6 | F14: 22.66 | G14: =E14*F14 -> 135.96
C15: ***THEY WILL NOT PROVIDE DUMMY INVOICE***
A17: FUND TRANSFER | B17: PAYMENT TERMS | C17: 30% ADVANCE | D17: =H7-G17 -> 9409.47 | F17: 70% AFTER PRODUCTION | G17: 20000
B18: PAYMENT STATUS | C18: PAID | F18: PAID
B19: PAYMENT DATE | C19: 46098 | F19: 46107
B20: SUBMITTED BY | C20: ARBAB | F20: ARBAB
B21: INV NO. | C21: 2026-EOC-001
A23: SHIPPER | B23: PRODUCTION STATUS
B24: SHIPPER'S REQUEST
B25: SHIPPER'S UPDATE
A27: FORWARDER | B27: FORWARDER
B28: FORWARDER'S REQUEST
B29: FORWARDER'S QUOTATION
B30: FORWARDER'S UPDATE
A32: COLLECTION / DELIVERY | B32: SHIPPER-FORWARDER STATUS | C32: CONNECTED
B33: COLLECTION DATE | C33: SHOULD BE BEFORE THE MARCH 27, 2026 (CUT OFF DATE)
B34: ETD: CHINA | C34: 46118
B35: ETA: UAE
B36: ETA: OFFICE
B37: DELIVERY STATUS | C37: IN TRANSIT
A39: MY ACTION / UPDATES | B39: LAST UPDATE | C39: # 8. Shipment arrived in Jebel Ali | Original Hard copies on hand | Paid 50% of AFC invoice
C40: 1. PO IS WITH LANA, ASKING FOR ARBAB'S APPROVAL
C41: 2. PO SENT TO IOB COMPANY FOR CONFIRMATION, WAITING FOR P.I.
C42: 3. RECEIVED PI AND PL, WILL PREPARE FUND TRANSFER
C43: 4. FIRST PAYMENT PAID | CONFIRMED FORWARDER | WILL PROCESS LAST PAYMENT (LANA) |SHIPPER AWAITING PICK UP CONFIRMATION
C44: 5. PROCESSING LAST PAYMENT | PICK UP: 26-03-2026 | ETD: 01-04-2026
C45: 6. COMPLETE PAYMENTS | DONE PICK UP: 27-03-2026| WAITING FOR DELIVERY AND STAMPED HARD COPIES OF DOCS FROM IOB
...

Sheet LABTEK - SLEEVES-MACHINE
A1: PO DETAILS | B1: YEAR | C1: 2026
B2: PO DATE | C2: 46086
B3: VENDOR | C3: Dalian Labtek Science & Development Co., LTD
B4: PO NO. | C4: PO/DLSD-2026/001
B5: ITEM | C5: LABTEK MACHINES AND SLEEVES
C6: ITEM CODE | D6: DESCRIPTION | E6: QTY | F6: PRICE USD | G6: TOTAL USD | H6: TOTAL USD
B7: ITEM 1 | C7: LBTK500-S | D7: COMPRESSION THIGH SCD SLEEVES - SMALL - 25PAIRS/BOX | E7: 350 | F7: 12 | G7: =E7*F7 -> 4200 | H7: =SUM(G7:G15) -> 45865
B8: ITEM 2 | C8: LBTK500-M | D8: COMPRESSION THIGH SCD SLEEVES - MEDIUM - 25PAIRS/BOX | E8: 900 | F8: 12 | G8: =E8*F8 -> 10800
B9: ITEM 3 | C9: LBTK500-L | D9: COMPRESSION THIGH SCD SLEEVES - LARGE - 20PAIRS/BOX | E9: 440 | F9: 12 | G9: =E9*F9 -> 5280
B10: ITEM 4 | C10: LBTK502-M | D10: COMPRESSION CALF SCD SLEEVES - MEDIUM - 40 PAIRS/BOX | E10: 600 | F10: 9 | G10: =E10*F10 -> 5400
B11: ITEM 5 | C11: LBTK502-L | D11: COMPRESSION CALF SCD SLEEVES - LARGE - 35 PAIRS/BOX | E11: 875 | F11: 9 | G11: =E11*F11 -> 7875
B12: ITEM 6 | C12: LBTK-M-I 5006 TOUCH SCREEN DISPLAY (Sequential + LITHIUM BATTERY) | D12: DVT Prevention Veinoflow SCD (Each set contains Power Cable *1, Air Tube *2) | E12: 15 | F12: 600 | G12: =E12*F12 -> 9000
B13: ITEM 7 | C13: LBTK-M-I 5005 TOUCH SCREEN DISPLAY (Sequential + LITHIUM BATTERY | D13: DVT Prevention Veinoflow SCD (Each set contains Power Cable *1, Air Tube *2) | E13: 5 | F13: 400 | G13: =E13*F13 -> 2000
B14: ITEM 8 | C14: Y.10.133 | D14: LCD SCREEN FOR LABTEK 5005 | E14: 5 | F14: 190 | G14: =E14*F14 -> 950
B15: ITEM 9 | C15: LABTEK BATTERY 5005 | D15: LABTEK BATTERY 5005 | E15: 2 | F15: 180 | G15: =E15*F15 -> 360
A17: FUND TRANSFER | B17: PAYMENT TERMS | C17: 30% ADVANCE | D17: =H7-G17 -> 13865 | F17: 70% AFTER PRODUCTION | G17: =32000 -> 32000
B18: PAYMENT STATUS | C18: PAID | F18: PAID
B19: PAYMENT DATE | C19: 46098 | F19: 46118
B20: SUBMITTED BY | C20: ARBAB | F20: MUJEEB
B21: INV NO. | C21: 20263108289
A23: SHIPPER | B23: PRODUCTION STATUS | C23: =C19+20+7 -> 46125
B24: SHIPPER'S REQUEST
B25: SHIPPER'S UPDATE | C25: ESTIMATED PRODUCTION FINISHING DATE
A27: FORWARDER | B27: FORWARDER
B28: FORWARDER'S REQUEST
B29: FORWARDER'S QUOTATION
B30: FORWARDER'S UPDATE
A32: COLLECTION / DELIVERY | B32: SHIPPER-FORWARDER STATUS
B33: COLLECTION DATE
B34: ETD: CHINA | C34: 46127
B35: ETA: UAE | C35: 46155
B36: ETA: OFFICE
B37: DELIVERY STATUS | C37: FOR PICKUP
C39: *** THIS SHIPMENT HAS DUMMY INVOICE ***
A40: MY ACTION / UPDATES | B40: LAST UPDATE / ACTION TAKEN | C40: # 7. MOH APPROVAL: PL WITH ALL DETAILS RECEIVED | FIRST PART PROCESSING BY NJ
C41: # 8. AFC: CONFIRMED: OCEAN FREIGHT + LOCAL CLEARANCE = AED8159.73 + CUSTOM DUTY +973.5( AED 13,233.23/- Approx) ETD：4.15 ETA：5.13
C42: 1. PO SENT TO LABTEK
C43: 2. FUND TRANSFER PREPARED. APPLICATION WITH AMR. WAITIING FOR ARBAB'S SIGN
C44: 3. FUND TRANSFER PREPARED. SIGNED BY ARBAB, WILL PROCESS ADVANCE PAYMENT
C45: 4. ADVANCE PAYMENT PAID | PRODUCTION: ONGOING | PACKING LIST: PENDING
...

Sheet ULTRASOUND GEL - TIANJIN
A1: PO DETAILS | B1: YEAR | C1: 2026
B2: PO DATE | C2: 46111
B3: VENDOR | C3: Tianjin Grand Paper Industry Co., Ltd
B4: PO NO. | C4: PO-TGP-2026-001
B5: ITEM | C5: ULTRASOUND GEL
C6: ITEM CODE | D6: DESCRIPTION | E6: QTY | F6: PRICE USD | G6: TOTAL USD | H6: TOTAL USD
B7: ITEM 1 | C7: YC.001 | D7: Ultrasound Gel 250 ML (Clear) | E7: 5000 | F7: 0.22 | G7: =E7*F7 -> 1100 | H7: =SUM(G7:G8) -> 2420
B8: ITEM 2 | C8: YC.002 | D8: Ultrasound Gel 250 ML (Blue) | E8: 6000 | F8: 0.22 | G8: =E8*F8 -> 1320
A10: FUND TRANSFER | B10: PAYMENT STATUS | C10: PAID
B11: PAYMENT DATE | C11: 46115
B12: SUBMITTED BY | C12: ARBAB VIA ADIB PROCESSED BY NJ
B13: INV NO. | C13: Z20260331
A15: SHIPPER | B15: PRODUCTION STATUS
B16: SHIPPER'S REQUEST
B17: SHIPPER'S UPDATE
A19: FORWARDER | B19: FORWARDER
B20: FORWARDER'S REQUEST
B21: FORWARDER'S UPDATE
A23: COLLECTION / DELIVERY | B23: SHIPPER-FORWARDER STATUS
B24: COLLECTION DATE
B25: ETD: CHINA | C25: NO DATE YET
B26: ETA: UAE
B27: ETA: OFFICE
B28: DELIVERY STATUS | C28: IN PRODUCTION
A30: MY ACTION / UPDATES | B30: LAST UPDATE | C30: # 4. WAITING FOR PACKING LIST, ONCE RECEIVED WILL ASK AFC FOR QUOTATION AND SCHEDULE
C31: 1. PO SENT TO TIANJIN
C32: 2. JE & NJ IS PROCESSING FUND TRANSFER WITH ARBAB
C33: 3. PAID 03-04-2026, FUND TRANSFER RECEIPT SENT TO TIANJIN
B38: ACTION TAKEN
B47: FILES
C48: AFC INVOICE
A50: EMAIL DETAILS | B50: EMAIL SUBJ: MANUFACTURER | C50: =C3&" ("&C5&") "&"-"&" "&C4 -> Tianjin Grand Paper Industry Co., Ltd (ULTRASOUND GEL) - PO-TGP-2026-001
B51: EMAIL SUBJ: FORWARDER | C51: ="AFC"&" ("&C$5&") "&"-"&" "&C$4&" - CHINA TO UAE" -> AFC (ULTRASOUND GEL) - PO-TGP-2026-001 - CHINA TO UAE

Sheet GAUZE - JIUJIANG HUADA
A1: PO DETAILS | B1: YEAR | C1: 2026
B2: PO DATE | C2: 46115
B3: VENDOR | C3: JIUJIANG HUADA MEDICAL DRESSING CO., LTD.
B4: PO NO. | C4: PO/JHMD-2026/001
B5: ITEM | C5: GAUZE
C6: ITEM CODE | D6: DESCRIPTION | E6: QTY | F6: PRICE USD | G6: TOTAL USD | H6: TOTAL USD
B7: ITEM 1 | C7: GSS2212 | D7: 5 X 5CM - 12PLY | E7: 6500 | F7: 0.798 | G7: =E7*F7 -> 5187 | H7: =SUM(G7:G11)-G12 -> 64504.25
B8: ITEM 2 | C8: GSS3312 | D8: 7.5 X 7.5CM - 12PLY | E8: 10000 | F8: 1.3 | G8: =E8*F8 -> 13000
B9: ITEM 3 | C9: GSS4412 | D9: 10 X 10CM - 12PLY | E9: 10800 | F9: 1.98 | G9: =E9*F9 -> 21384
B10: ITEM 4 | C10: GSS4412X | D10: 10 X 10CM - 12PLY WITH X-RAY | E10: 10920 | F10: 2.15 | G10: =E10*F10 -> 23478
B11: ITEM 5 | C11: GS2212 | D11: 5 X 5 CM – 12 PLY | E11: 5000 | F11: 0.395 | G11: =E11*F11 -> 1975
F12: CREDIT BALANCE | G12: 519.75
A14: FUND TRANSFER | B14: AMOUNT | C14: 22529.25 | E14: =H7-C14 -> 41975
B15: PAYMENT STATUS | C15: FIRST PAYMENT - PAID | E15: LAST PAYMENT - NOT YET PAID
B16: PAYMENT DATE | C16: 46126
B17: SUBMITTED BY | C17: MUJEEB
B18: INV NO. | C18: HDK260406
A20: SHIPPER | B20: PRODUCTION STATUS
B21: SHIPPER'S REQUEST
B22: SHIPPER'S UPDATE
A24: FORWARDER | B24: FORWARDER
B25: FORWARDER'S REQUEST
B26: FORWARDER'S UPDATE
A28: COLLECTION / DELIVERY | B28: SHIPPER-FORWARDER STATUS
B29: COLLECTION DATE
B30: ETD: CHINA | C30: NO DATE YET
B31: ETA: UAE
B32: ETA: OFFICE
B33: DELIVERY STATUS | C33: IN PRODUCTION
C34: *** THIS HAS DUMMY INVOICE *** already noted not to send invoice to forwarders
A35: MY ACTION / UPDATES | B35: LAST UPDATE | C35: # 2. PAID - WAITING FOR PACKING LIST
C36: 1. PO CREATED, SENT TO JIUJIANG HUADA WAITING FOR PROFORMA INVOICE
C37: 2. PROFORMA INVOICE RECEIVE, WILL PROCESS THE PAYMENT
B43: ACTION TAKEN
B52: FILES
C53: AFC INVOICE
A55: EMAIL DETAILS | B55: EMAIL SUBJ: MANUFACTURER | C55: =C3&" ("&C5&") "&"-"&" "&C4 -> JIUJIANG HUADA MEDICAL DRESSING CO., LTD. (GAUZE) - PO/JHMD-2026/001
B56: EMAIL SUBJ: FORWARDER | C56: ="AFC"&" ("&C$5&") "&"-"&" "&C$4&" - CHINA TO UAE" -> AFC (GAUZE) - PO/JHMD-2026/001 - CHINA TO UAE

Sheet STOCKINGS - VARIMED
A1: PO DETAILS | B1: YEAR | C1: 2026
B2: PO DATE | C2: 46057
B3: VENDOR | C3: Varimed Medikal San. Ve. Tic. Ltd.
B4: PO NO. | C4: PO-VARIMED-2026-001
B5: ITEM | C5: STOCKINGS
C6: ITEM CODE | D6: DESCRIPTION | E6: QTY | F6: PRICE EUR | G6: TOTAL EUR | H6: TOTAL EUR
B7: ITEM 1 | C7: 6121S | D7: AG-Thigh Length,with Dotted silicone topband,Anti-Embolism Stocking (Pair)- S | E7: 120 | F7: 2.9 | G7: =(E7*F7) -> 348 | H7: =SUM(G7:G11)-G12 -> 13363.2
B8: ITEM 2 | C8: 6121M | D8: AG-Thigh Length,with Dotted silicone topband,Anti-Embolism Stocking (Pair)- M | E8: 500 | F8: 2.9 | G8: =(E8*F8) -> 1450
B9: ITEM 3 | C9: 6121L | D9: AG-Thigh Length,with Dotted silicone topband,Anti-Embolism Stocking (Pair)- L | E9: 500 | F9: 2.9 | G9: =(E9*F9) -> 1450
B10: ITEM 4 | C10: 6121XL | D10: AG-Thigh Length,with Dotted silicone topband,Anti-Embolism Stocking (Pair)- XL | E10: 2000 | F10: 2.9 | G10: =(E10*F10) -> 5800
B11: ITEM 5 | C11: 6121XXL | D11: AG-Thigh Length,with Dotted silicone topband,Anti-Embolism Stocking (Pair)- XXL | E11: 2000 | F11: 2.9 | G11: =(E11*F11) -> 5800
F12: DISCOUNT 10 % | G12: =SUM(G7:G11)*0.1 -> 1484.8
A14: FUND TRANSFER | B14: PAYMENT STATUS | C14: PAID
B15: PAYMENT DATE | C15: 46064
B16: SUBMITTED BY | C16: MUJEEB
B17: INV NO. | C17: 20260206
A19: SHIPPER | B19: PRODUCTION STATUS
B20: SHIPPER'S REQUEST
B21: SHIPPER'S UPDATE | C21: PLANNED DELIVERY DATE: 06-04-2026
A23: FORWARDER | B23: FORWARDER
B24: FORWARDER'S REQUEST
B25: FORWARDER'S UPDATE | C25: LATEST AIR FREIGHT SCHEDULE 07-04-2026
A27: COLLECTION / DELIVERY | B27: SHIPPER-FORWARDER STATUS | C27: WAITING FOR AGENT DETAILS
B28: COLLECTION DATE | C28: 06/04/2026 TENTATIVE
B29: ETD: CHINA | C29: DEPARTED
B30: ETA: UAE
B31: ETA: OFFICE | C31: 46132
B32: DELIVERY STATUS | C32: RECEIVED: 21-04-2026
C34: *** THIS HAS DUMMY INVOICE *** already noted not to send invoice to forwarders
A35: MY ACTION / UPDATES | B35: LAST UPDATE | C35: # 13. AFC INVOICE PAID 24-04-2026
C36: 1. SENT PO TO MANUFACTURER
C37: 2. PI RECEIVED, WILL PROCESS FUND TRANSFER
C38: 3. FUND TRANSFER DETAILS CONFIRMED BY VARIMED, WILL ASK FOR ARBAB'S SIGN WHEN AVAILABLE
C39: 4. FUND TRANSFER SIGNED, WILL GIVE TO MUJEEB TO PROCESS THE PAYMENT
C40: 5. FUND TRANSFER RECEIPT SENT, WILL WAIT FOR PACKING LIST TO SEND TO FORWARDERS
C41: 6. PRODUCTION: ONGOING | PACKING LIST: PENDING
C42: 7. PRODUCTION: ONGOING | PACKING LIST & DUMMY INVOICE: PENDING | OCEAN FREIGHT + LOCAL CLEARANCE = AED 5129.73+ CUSTOM DUTY +873.5( AED 6,003.23 + CUSTOMS DUTY /- Approx)
C43: 7. PRODUCTION: ONGOING | PACKING LIST & DUMMY INVOICE: PENDING | AIR FREIGHT + LOCAL CLEARANCE = AED 8924.17 + CUSTOM DUTY ACTUAL + 1100 ( AED 10,024.17+ CUSTOMS DUTY /- Approx)
C44: 8. GAMZE: WAITING FOR UPDATED PACKING LIST
B45: ACTION TAKEN | C45: 8. AFC: ONCE PACKING LIST IS RECEIVED, WILL ASK FALAH FOR QUOTATION AND SCHEDULE
...

Sheet ELECTROSURGICAL PENCIL - ZHEJIA
A1: PO DETAILS | B1: YEAR | C1: 2026
B2: PO DATE | C2: 46077
B3: VENDOR | C3: Zhejiang Medstar Technology Co., Ltd
B4: PO NO. | C4: PO-ZMTC-2026-001
B5: ITEM | C5: PUSH BUTTON ELECTROSURGICAL PENCIL
C6: ITEM CODE | D6: DESCRIPTION | E6: QTY | F6: PRICE USD | G6: TOTAL USD | H6: TOTAL USD
B7: ITEM 1 | C7: PN03-050 | D7: Push Button electrosurgical pencil, 70mm SS blade,3.0m cord with 3-prong plug | E7: 1000 | F7: 0.6 | G7: =(E7*F7) -> 600 | H7: =SUM(G7:G7) -> 600
A9: FUND TRANSFER | B9: PAYMENT STATUS
B10: PAYMENT DATE
B11: SUBMITTED BY
B12: INV NO.
A14: SHIPPER | B14: PRODUCTION STATUS
B15: SHIPPER'S REQUEST
B16: SHIPPER'S UPDATE
A18: FORWARDER | B18: FORWARDER
B19: FORWARDER'S REQUEST
B20: FORWARDER'S UPDATE
A22: COLLECTION / DELIVERY | B22: SHIPPER-FORWARDER STATUS
B23: COLLECTION DATE
B24: ETD: CHINA
B25: ETA: UAE
B26: ETA: OFFICE
B27: DELIVERY STATUS
A30: MY ACTION / UPDATES | B30: LAST UPDATE | C30: # 1. PO CREATED, SENT TO AMR FOR ARBAB'S APPROVAL - CANCELLED
B40: ACTION TAKEN
B45: FILES | C45: AFC INVOICE
A48: EMAIL DETAILS | B48: EMAIL SUBJ: MANUFACTURER | C48: =C3&" ("&C5&") "&"-"&" "&C4 -> Zhejiang Medstar Technology Co., Ltd (PUSH BUTTON ELECTROSURGICAL PENCIL) - PO-ZMTC-2026-001
B49: EMAIL SUBJ: FORWARDER | C49: ="AFC"&" ("&C$5&") "&"-"&" "&C$4&" - CHINA TO UAE" -> AFC (PUSH BUTTON ELECTROSURGICAL PENCIL) - PO-ZMTC-2026-001 - CHINA TO UAE

Sheet SWAB APPLICATOR
A1: PO DETAILS | B1: YEAR
B2: PO DATE
B3: VENDOR
B4: PO NO.
B5: ITEM | C5: SWAB APPLICATOR
C6: ITEM CODE | D6: DESCRIPTION | E6: QTY | F6: PRICE USD | G6: TOTAL USD | H6: TOTAL USD
B7: ITEM 1 | G7: =(E7*F7) -> 0 | H7: =SUM(G7:G8) -> 0
C8: ***THEY WILL NOT PROVIDE DUMMY INVOICE***
A10: FUND TRANSFER | B10: PAYMENT STATUS
B11: PAYMENT DATE
B12: SUBMITTED BY
B13: INV NO.
A15: SHIPPER | B15: PRODUCTION STATUS
B16: SHIPPER'S REQUEST
B17: SHIPPER'S UPDATE
A19: FORWARDER | B19: FORWARDER
B20: FORWARDER'S REQUEST
B21: FORWARDER'S UPDATE
A23: COLLECTION / DELIVERY | B23: SHIPPER-FORWARDER STATUS
B24: COLLECTION DATE
B25: ETD: CHINA
B26: ETA: UAE
B27: ETA: OFFICE
B28: DELIVERY STATUS
A31: MY ACTION / UPDATES | B31: LAST UPDATE
B41: ACTION TAKEN
B46: FILES
A49: EMAIL DETAILS | B49: EMAIL SUBJ: MANUFACTURER | C49: =C3&" ("&C5&") "&"-"&" "&C4 -> (SWAB APPLICATOR) -
B50: EMAIL SUBJ: FORWARDER | C50: ="AFC"&" ("&C$5&") "&"-"&" "&C$4&" - CHINA TO UAE" -> AFC (SWAB APPLICATOR) - - CHINA TO UAE

Sheet VEIN VIEWER
A1: PO DETAILS | B1: YEAR
B2: PO DATE
B3: VENDOR
B4: PO NO.
B5: ITEM | C5: PROJECTION VEIN FINDER
C6: ITEM CODE | D6: DESCRIPTION | E6: QTY | F6: PRICE USD | G6: TOTAL USD | H6: TOTAL USD
B7: ITEM 1 | G7: =E7*F7 -> 0 | H7: =SUM(G7:G8) -> 0
B8: ITEM 2 | G8: =E8*F8 -> 0
A10: FUND TRANSFER | B10: PAYMENT STATUS
B11: PAYMENT DATE
B12: SUBMITTED BY
B13: INV NO.
A15: SHIPPER | B15: PRODUCTION STATUS
B16: SHIPPER'S REQUEST
B17: SHIPPER'S UPDATE
A19: FORWARDER | B19: FORWARDER
B20: FORWARDER'S REQUEST
B21: FORWARDER'S UPDATE
A23: COLLECTION / DELIVERY | B23: SHIPPER-FORWARDER STATUS
B24: COLLECTION DATE
B25: ETD: CHINA
B26: ETA: UAE
B27: ETA: OFFICE
B28: DELIVERY STATUS
C30: |
A31: MY ACTION / UPDATES | B31: LAST UPDATE
B41: ACTION TAKEN
B46: FILES
C47: FREIGHT CHARGE (DHL) | D47: VIVO-20251218229 | E47: 260.00 USD
A49: EMAIL DETAILS | B49: EMAIL SUBJ: MANUFACTURER | C49: =C3&" ("&C5&") "&"-"&" "&C4 -> (PROJECTION VEIN FINDER) -
B50: EMAIL SUBJ: FORWARDER | C50: DELIVERY: WILL BE DIRECT FROM VIVO NO NEED FOR AGENTS

Sheet SLEEVES - Suzhou Minha
A1: PO DETAILS | B1: YEAR
B2: PO DATE
B3: VENDOR | C3: Suzhou Minha Medical Equipment Co., LTD
B4: PO NO.
B5: ITEM | C5: SLEEVES
C6: ITEM CODE | D6: DESCRIPTION | E6: QTY | F6: PRICE USD | G6: TOTAL USD | H6: TOTAL USD
B7: ITEM 1 | G7: =E7*F7 -> 0 | H7: =SUM(G7:G8) -> 0
B8: ITEM 2 | G8: =E8*F8 -> 0
A10: FUND TRANSFER | B10: PAYMENT STATUS
B11: PAYMENT DATE
B12: SUBMITTED BY
B13: INV NO.
A15: SHIPPER | B15: PRODUCTION STATUS
B16: SHIPPER'S REQUEST
B17: SHIPPER'S UPDATE
A19: FORWARDER | B19: FORWARDER
B20: FORWARDER'S REQUEST
B21: FORWARDER'S UPDATE
A23: COLLECTION / DELIVERY | B23: SHIPPER-FORWARDER STATUS
B24: COLLECTION DATE
B25: ETD: CHINA
B26: ETA: UAE
B27: ETA: OFFICE
B28: DELIVERY STATUS
A31: MY ACTION / UPDATES | B31: LAST UPDATE
B38: ACTION TAKEN
B42: FILES
A47: EMAIL DETAILS | B47: EMAIL SUBJ: MANUFACTURER | C47: =C1&" ("&C2&") "&"-"&" "&C2 -> () -
B48: EMAIL SUBJ: FORWARDER | C48: ="AFC"&" ("&C$5&") "&"-"&" "&C$4&" - CHINA TO UAE" -> AFC (SLEEVES) - - CHINA TO UAE

Sheet GAUZE - JIUJANG HUADA
A1: PO DETAILS | B1: YEAR
B2: PO DATE
B3: VENDOR | C3: JIUJANG HUADA MEDICAL DRESSING CO., LTD
B4: PO NO.
B5: ITEM | C5: GAUZE (SAMPLES)
C6: ITEM CODE | D6: DESCRIPTION | E6: QTY | F6: PRICE USD | G6: TOTAL USD | H6: TOTAL USD
B7: ITEM 1 | G7: =(E7*F7) -> 0 | H7: =SUM(G7:G8) -> 0
B8: ITEM 2
A10: FUND TRANSFER | B10: PAYMENT STATUS
B11: PAYMENT DATE
B12: SUBMITTED BY
B13: INV NO.
A15: SHIPPER | B15: PRODUCTION STATUS
B16: SHIPPER'S REQUEST
B17: SHIPPER'S UPDATE
A19: FORWARDER | B19: FORWARDER
B20: FORWARDER'S REQUEST
B21: FORWARDER'S UPDATE
A23: COLLECTION / DELIVERY | B23: SHIPPER-FORWARDER STATUS
B24: COLLECTION DATE
B25: ETD: CHINA
B26: ETA: UAE
B27: ETA: OFFICE
B28: DELIVERY STATUS
A31: MY ACTION / UPDATES | B31: LAST UPDATE
B35: ACTION TAKEN
B40: FILES | C40: 1. AFC INVOICE [RECEIVED]
A43: EMAIL DETAILS | B43: EMAIL SUBJ: MANUFACTURER
B44: EMAIL SUBJ: FORWARDER | C44: ="AFC"&" ("&C$5&") "&"-"&" "&C$4&" - CHINA TO UAE" -> AFC (GAUZE (SAMPLES)) - - CHINA TO UAE

Sheet DDL
A1: ITEM | B1: COMPANY | C1: STATUS
A2: ULTRASOUND GEL | B2: Tianjin Grand Paper Industry Co., Ltd | C2: WAITING FOR INVOICE AND PACKING LIST
A3: BLANKET | B3: Jiangmen Dacheng Medical Equipment Co., Ltd | C3: WAITING FOR SCHEDULE
A4: SLEEVES | B4: Suzhou Minha Medical Equipment Co., LTD | C4: WAITING FOR DUMMY INVOICE AND PACKING LIST
C5: WAITING FOR INVOICE AND SCHEDULE
C6: PRODUCTION
C7: RECEIVED INVOICE
C8: PAID
C9: UNPAID
C10: PENDING
C11: DELIVERY SCHEDULED
C12: FOLLOW UP EMAIL
C13: WAITING FOR DUMMY INVOICE

Sheet Monitor
F1: PURCHASE ORDER | L1: FUND TRANSFER | P1: SHIPPER | T1: FORWARDER | V1: COLLECTION / DELIVERY | AB1: MY ACTIONS AND UPDATES | AE1: EMAIL DETAILS
A2: YEAR | B2: PO DATE | C2: VENDOR | D2: PO/INV NO. | E2: ITEM | F2: ITEM CODE | G2: DESC | H2: QTY | I2: PRICE USD | J2: TOTAL USD | K2: TOTAL USD | L2: PAYMENT STATUS | M2: PAYMENT DATE | N2: SUBMITTED BY | O2: INV NO. | P2: PRODUCTION STATUS | Q2: SHIPPER'S REQUEST | R2: SHIPPERS UPDATE | S2: FORWARDER | T2: FORWARDER'S REQUEST | U2: FORWARDER'S UPDATE | V2: SHIPPER - FORWARDER STATUS | W2: COLLECTION DATE | X2: ETD: CHINA | Y2: ETA: UAE | Z2: ETA: OFFICE | AA2: DELIVERY STATUS | AB2: LAST UPDATE | AC2: ACTIONS TAKEN | AD2: FILES | AE2: EMAIL SUBJ MANUFACTURER | AF2: EMAIL SUBJ: FORWARDER | AG2: GC UPDATE
A3: 2025 | B3: 45841 | C3: Tianjin Grand Paper Industry Co., Ltd | D3: PO-TGP-2025-001 | E3: ULTRASOUND GEL | F3: YC.002 | G3: Ultrasound Gel 250 ML (Blue) | H3: 6000 | I3: 0.22 | J3: 1320 | K3: =SUM(J3:J4) -> 1561.5 | L3: PAID | M3: 45912 | N3: ARBAB / JE (ADIB) | P3: COLLECTED | V3: CONNECTED | W3: 45918 | X3: 45923 | AB3: 1. BANK PAYMENT (ADIB) [DONE] 2. TIANJIN AND AFC AGENT [CONNECTED] 3. TIANJIN ASKING FOR TRADE LICENSE AND PASSPORT (SENT) 4. CHANGES IN CMB AND CTN QTY (PACKING LIST) | AC3: 1. SENT PROOF OF PAYMENT TO TIANJIN 2. SENT TRADE LICENSE AND PASSPORT TO TIANJIN 3. PL SENT TO GC 4. ASK FOR UPDATED PACKING LIST | AD3: 1. FEDEX FILES 2. AFC INVOICE | AE3: Tianjin Grand Paper (Ultrasound Gel) | Purchase Order #001 | AF3: AFC - PO-TGP-2025-001 | CHINA TO UAE
F4: NULL | G4: Empty Bottles 250 ML | H4: 2100 | I4: 0.115 | J4: 241.5
B5: 45852 | C5: Jiangmen Dacheng Medical Equipment Co., Ltd | D5: PO-IOB-2025-003 | E5: BLANKET/MACHINE SPARE PARTS | F5: IOB-004 | G5: Warming Blanket Adult Full Body 83”x47’’ (210 cm x 120 cm) | H5: 10000 | I5: 2.2 | J5: 22000 | K5: =SUM(J5:J11) -> 29256 | L5: PAID | M5: 45862 | N5: MUJEEB | P5: COLLECTED | S5: AFC | V5: CONNECTED | Y5: 45900 | Z5: 45901 | AA5: SHIPMENT RECEIVE DATE: 10-09-2025 STATUS: COMPLETE PO UPDATED HARD COPY FILES | AB5: 1. FEDEX DOCS RECEIVED 2. ITEMS DELIVERED | AC5: 1. AFC INVOICE WITH SIGNED DOCUMENTS SENT TO ACCOUNTING | AD5: 1. FEDEX FILES [RECEIVED] TRK# 8837 9809 1137 2. AFC INVOICE [RECEIVED] INV. 05752 (12,976.50 AED) | AE5: Jiangmen Dacheng Medical Equipment Co., Ltd (IOB) - PO/IOB-2025/003 | AF5: AFC - PO/IOB-2025/003 | CHINA TO UAE | AG5: AMR UPDATES ABOUT THE APPROXIMATE TIME WE WILL RECEIVE ITEMS IN OFFICE
F6: IOB-003 | G6: Warming Blanket Upper Body 80" x 25" (202 cm x 64 cm) | H6: 1400 | I6: 2.2 | J6: 3080
F7: IOB-002 | G7: Intraoperative Warming Blanket Lower Body 62" x 46" (142 cm x 120 cm) | H7: 400 | I7: 2.2 | J7: 880
F8: IOB-028 | G8: Pediatric Warming Blanket Infant Under Body 39" x 39" (100cm X 100cm) | H8: 280 | I8: 2.2 | J8: 616
F9: IOB-016 | G9: Surgical Access Warming Blanket 83" x 47" (210cm x 120cm) | H9: 400 | I9: 2.2 | J9: 880
F10: WU-5-006 | G10: Base Board (for 505 machine) | H10: 5 | I10: 120 | J10: 600
F11: WU-007 | G11: Air Hose with Sensor One Cord | H11: 10 | I11: 120 | J11: 1200
B12: 45855 | C12: Suzhou Minha Medical Equipment Co., LTD | D12: PO-SMME-2025-001 | E12: SLEEVES | F12: BOV-300-M | G12: Thigh Length SCD Sleeves - Medium | H12: 2350 | I12: 13 | J12: 30550 | K12: =SUM(J12:J13) -> 39000 | L12: PAID | M12: 45862 | N12: MUJEEB | P12: Shipper informed to collect the cargo by 29 AUG | S12: AFC | V12: CONNECTED | W12: 08/09/2025 (SEA) | X12: 12/09/2025 (SEA) | Y12: TT: 22 DAYS / 02-10-2025 | Z12: SLEEVES BY AIR, BOV-300-M(500 PCS) RECEIVED: 06/09/2025 SLEEVES BY SEA, WILL RECEIVE: END OF THIS MONTH | AA12: 1. RECEIVED: BOV-300-M (500 PCS) 06-09-2025 2. NOTE: MORE PENDING ITEMS TO BE RECEIVED | AB12: 1. BOV-300-M(500 PCS)RECEIVED: 06/09/2025 - BY AIR 2. PENDING ITEMS TO RECEIVE (BY SEA) | AC12: 1. CONFIRMED BOOKING DETAILS AND ASK APPROXIMATE DELIVERY DATE 2. CONFIRMED DRAFT BL | AD12: 1. AFC INVOICE (AIR) [RECEIVED] INV. 05740 (8926.00 AED) 2. DRAFT BL (SEA) [RECEIVED] 3. SIGNED - ORIGINAL AND DUMMY INVOICE, PACKING LIST, COO | AE12: Suzhou Minha Medical Equipment Co. LTD (Sleeves) - PO/SMME-2025/001 | AF12: AFC - PO/SMME-2025/001 | CHINA TO UAE | AG12: `SLEEVES BY AIR, BOV-300-M(500 PCS) RECEIVED: 06/09/2025; `SLEEVES BY SEA, WILL RECEIVE: END OF THIS MONTH
F13: BOV-300-S | G13: Thigh Length SCD Sleeves - Small | H13: 650 | I13: 13 | J13: 8450
B14: 45887 | C14: JIUJANG HUADA MEDICAL DRESSING CO., LTD | D14: HDK250818 | E14: GAUZE (SAMPLE) | F14: GSS4416X | G14: Gauze Swab Sterile - 10x10-16Ply with X-Ray 13T (5PCS/PACK, 20PACKS/BOX, FOLDED EDGE DOUBLE PACK) | H14: 200 | I14: 2.75 | J14: =(H14*I14) -> 550 | K14: =SUM(J14,J15) -> 695 | L14: PAID | M14: 45887 | N14: MUJEEB | P14: COLLECTED | S14: AFC | V14: CONNECTED | W14: COLLECTED | Y14: ARRIVED | Z14: RECEIVED: 17-09-2025 | AA14: SHIPMENT RECEIVE DATE: 17-09-2025 STATUS: COMPLETE PO/SAMPLES | AB14: 1. ITEMS ARE COLLECTED AND ALREADY IN TRANSIT 2. ITEMS RECEIVED | AC14: 1. AMR SENT SHIPPER DETAILS TO AFC 2. ASKED AGENT'S DETAILS TO SEND TO SHIPPERS 3. ASK AFC ABOUT SHIPMENT STATUS 4. UPDATE DELIVERY DETAILS IN GC 5. SHARED AFC INVOICE, PL AND PI TO ACCOUNTING | AD14: 1. FEDEX FILES 2. AFC INVOICE [RECEIVED] INV. 05856 (1,100 AED) | AE14: JIUJANG HUADA MEDICAL DRESSING CO., LTD (GAUZE) - INV - HDK250818 - 001 | AF14: AFC - INV - HDK250818 - 001 | CHINA TO UAE
F15: NULL | G15: BOX | J15: 145
B16: 45887 | C16: Jiangmen Dacheng Medical Equipment Co., Ltd | D16: PO-IOB-2025-004 | E16: BLANKET | F16: IOB-004 | G16: Intraoperative Warming Blanket Adult Full Body 83" x 47" (210 cm x 120 cm) 40/box | H16: 3000 | I16: 2.2 | J16: =(H16*I16) -> 6600 | K16: =SUM(J16:J20) -> 10560 | L16: PAID | M16: 45896 | N16: MUJEEB | P16: COLLECTED | S16: AFC | V16: CONNECTED | W16: 45908 | X16: 1. 14/09/2025 2. 18/09/2025 delay reason: port congestion loaded and selected for random custom checking | AB16: 1. COLLECTED 2. ITEMS LOADED AND SELECTED FOR CUSTOM CHECKING | AC16: 1.CONNECTING FORWARDER TO SHIPPER 2. Draft BL confirmed for AFC | AD16: 1. SIGNED (PL, PI, CO) [RECEIVED] 2. FEDEX FILES 3. AFC INVOICE | AE16: Jiangmen Dacheng Medical Equipment Co., Ltd (IOB) - PO-IOB-2025-004 | AF16: AFC - PO-IOB-2025-004 | CHINA TO UAE
F17: IOB-008 | G17: Postoperative Warming Blanket Full Body Surgical 83" x 47" (210cm X 120cm) | H17: 600 | I17: 2.2 | J17: =(H17*I17) -> 1320
F18: IOB-009 | G18: Large Pediatric Under Body 36" x 31"(160cm x 80cm) | H18: 600 | I18: 2.2 | J18: =(H18*I18) -> 1320
F19: IOB-002 | G19: Intraoperative Warming Blanket Lower Body 62" x 46" (142 cm x 120 cm) | H19: 400 | I19: 2.2 | J19: =(H19*I19) -> 880
F20: IOB-028 | G20: Pediatric Warming Blanket Infant Under Body 39" x 39" (100cm X 100cm) | H20: 200 | I20: 2.2 | J20: =(H20*I20) -> 440
B21: 45887 | C21: Dongguan Tondaus Meditech Co., LTD | D21: PO-DTMCL-2025-002 | E21: SKIN MARKER | F21: TR03 | G21: Surgical Skin Marker Single Side | H21: 6000 | I21: 0.21 | J21: =(H21*I21) -> 1260 | K21: =SUM(J21:J22) -> 14460 | L21: PAID | M21: 45891 | N21: MUJEEB | P21: ONGOING - WILL BE READY AROUND 10-10-2025 | W21: AFTER SEPT-OCT HOLIDAY | AB21: 1. ONGOING PRODUCTION: WILL BE READY ABOUT 10-10-2025 | AC21: 1. ASK FOR PRODUCTION STATUS 2. ASK IF THEY CAN EXPEDITE OUR ORDER | AD21: 1. DELIVERY SCHEDULE, PACKING LIST | AE21: Dongguan Tondaus Meditech Co., LTD (SKIN MARKER) - PO-DTMCL-2025-002 | AF21: AFC - PO-DTMCL-2025-002 (SKIN MARKER) | CHINA TO UAE
F22: TD01 | G22: Surgical Skin Marker Double Side | H22: 60000 | I22: 0.22 | J22: =(H22*I22) -> 13200
B23: 45840 | C23: Dalian Labtek Science and Development Co., Ltd | D23: SLEEVES SAMPLES - INV-202506196848 | E23: SLEEVES (SAMPLE) | F23: LBTK500-SM,L; LBTK-502-M,L,XL | G23: COMPRESSION SLEEVES | H23: 24 | I23: 6.26 | J23: =(H23*I23) -> 150.24 | K23: =SUM(J23:J24)&" (150.20 in Proforma Invoice)" -> 150.24 (150.20 in Proforma Invoice) | L23: AMR | M23: AMR | N23: AMR | P23: COLLECTED | S23: AMR | V23: AMR | W23: AMR | X23: AMR | Y23: AMR | Z23: 45910 | AA23: SHIPMENT RECEIVE DATE: 11-09-2025 STATUS: COMPLETE PO/SAMPLES UPDATED HARD COPY FILES | AB23: DELIVERED | AC23: 1. AFC INVOICE WITH DOCUMENTS GIVEN TO GETHEEKA ACCOUNTANT | AD23: 1. FEDEX FILES 2. AFC INVOICE [RECEIVED] INV. 05803 (800.00 AED) | AE23: AMR | AF23: Request for Best Shipping Offer – LABTEK Shipment | AG23: AMR: APPROXIMATE DELIVERY DATE: 10-09-2025

Sheet Sheet1
A1: AFC | C1: FASTCONNECT
A2: 1260 | C2: 2790
A3: 100
A4: 250
A5: =SUM(A2:A4) -> 1610
B6: =A5+A12 -> 2573.4
A7: 239.9
A8: 300
A9: 73.5
A10: 100
A11: 250
A12: =SUM(A7:A11) -> 963.4
